Workbook

Sheet LISTA DE ATLETAS
A1: CÉLULA | B1: EQUIPE | C1: NOME | D1: APELIDO | E1: ANO | F1: INSTAGRAM | G1: NÚMERO | H1: NOME + TIME
A2: 1 | B2: LUS USP RP | D2: LOBA | F2: J.FAGUNDEZ | G2: 8 | H2: =CONCATENATE(D2," - ",B2) -> LOBA - LUS USP RP
A3: 2 | B3: LUS USP RP | D3: CHARLIE | F3: REHVINHAGA | G3: 11 | H3: =CONCATENATE(D3," - ",B3) -> CHARLIE - LUS USP RP
A4: 3 | B4: LUS USP RP | D4: PICK | F4: LIVIARCARVALHO | G4: 13 | H4: =CONCATENATE(D4," - ",B4) -> PICK - LUS USP RP
A5: 4 | B5: LUS USP RP | D5: ELÉTRICA | F5: MARII_CAMOLEZ | G5: 16 | H5: =CONCATENATE(D5," - ",B5) -> ELÉTRICA - LUS USP RP
A6: 5 | B6: LUS USP RP | D6: DANONE | F6: CLARABERTOLAA | G6: 21 | H6: =CONCATENATE(D6," - ",B6) -> DANONE - LUS USP RP
A7: 6 | B7: LUS USP RP | D7: XANDRITA | F7: RITINHACARON | G7: 26 | H7: =CONCATENATE(D7," - ",B7) -> XANDRITA - LUS USP RP
A8: 7 | B8: LUS USP RP | D8: BABY | F8: MARIAEDUARDA_FRANCELINO | G8: 31 | H8: =CONCATENATE(D8," - ",B8) -> BABY - LUS USP RP
A9: 8 | B9: LUS USP RP | D9: SUFOCO | F9: BIA_ANDRADE175 | G9: 94 | H9: =CONCATENATE(D9," - ",B9) -> SUFOCO - LUS USP RP
A10: 9 | B10: LUS USP RP | D10: BANHO | G10: 98 | H10: =CONCATENATE(D10," - ",B10) -> BANHO - LUS USP RP
A11: 10 | B11: LUS USP RP | D11: MABS | F11: sarahsolovi | G11: 24 | H11: =CONCATENATE(D11," - ",B11) -> MABS - LUS USP RP
A12: 11 | B12: LUS USP RP | D12: MARIÊ | F12: gabmariefs | G12: 94 | H12: =CONCATENATE(D12," - ",B12) -> MARIÊ - LUS USP RP
A13: 12 | B13: LUS USP RP | D13: PURURUCA | H13: =CONCATENATE(D13," - ",B13) -> PURURUCA - LUS USP RP
A14: 13 | B14: LUS USP RP | D14: BT | H14: =CONCATENATE(D14," - ",B14) -> BT - LUS USP RP
A15: 14 | B15: FILÔ USP RP | D15: REBECA | F15: BECKS_MACHADO | G15: 4 | H15: =CONCATENATE(D15," - ",B15) -> REBECA - FILÔ USP RP
A16: 15 | B16: FILÔ USP RP | D16: JADE | F16: LETICIAPPENEDO | G16: 7 | H16: =CONCATENATE(D16," - ",B16) -> JADE - FILÔ USP RP
A17: 16 | B17: FILÔ USP RP | D17: ZIMI | F17: SOFIACASARI | G17: 9 | H17: =CONCATENATE(D17," - ",B17) -> ZIMI - FILÔ USP RP
A18: 17 | B18: FILÔ USP RP | D18: COLÔ | F18: ANAJULIALP | G18: 11 | H18: =CONCATENATE(D18," - ",B18) -> COLÔ - FILÔ USP RP
A19: 18 | B19: FILÔ USP RP | D19: QUIRO | F19: MARIA_SILVA207 | G19: 14 | H19: =CONCATENATE(D19," - ",B19) -> QUIRO - FILÔ USP RP
A20: 19 | B20: FILÔ USP RP | D20: AMINA | F20: DANII.TRINDADE | G20: 23 | H20: =CONCATENATE(D20," - ",B20) -> AMINA - FILÔ USP RP
A21: 20 | B21: FILÔ USP RP | D21: WINNIE | F21: LARI_RR_ | G21: 24 | H21: =CONCATENATE(D21," - ",B21) -> WINNIE - FILÔ USP RP
A22: 21 | B22: FILÔ USP RP | D22: DRIVE | F22: MALU.FURCOLIN | G22: 30 | H22: =CONCATENATE(D22," - ",B22) -> DRIVE - FILÔ USP RP
A23: 22 | B23: FILÔ USP RP | D23: PONTUAL | F23: RAYANEVIVEIROS_ | G23: 32 | H23: =CONCATENATE(D23," - ",B23) -> PONTUAL - FILÔ USP RP
A24: 23 | B24: FILÔ USP RP | D24: CATI | F24: CATIZULQUES | G24: 44 | H24: =CONCATENATE(D24," - ",B24) -> CATI - FILÔ USP RP
A25: 24 | B25: FILÔ USP RP | D25: TECA | F25: LEILA_HARTVITE | G25: 80 | H25: =CONCATENATE(D25," - ",B25) -> TECA - FILÔ USP RP
A26: 25 | B26: FILÔ USP RP | D26: KESHA | E26: 6 | F26: ANACSFCOSTA | G26: 8 | H26: =CONCATENATE(D26," - ",B26) -> KESHA - FILÔ USP RP
A27: 26 | B27: FILÔ USP RP | D27: TURQUI | E27: 1 | F27: GABIRELA_T.MENDES | G27: 32 | H27: =CONCATENATE(D27," - ",B27) -> TURQUI - FILÔ USP RP
A28: 27 | B28: MED UNAERP | D28: AMANDA | F28: MANDABERTOLUCCI | G28: 9 | H28: =CONCATENATE(D28," - ",B28) -> AMANDA - MED UNAERP
A29: 28 | B29: MED UNAERP | D29: MAFÊ | F29: MFERRODRIGUES | G29: 18 | H29: =CONCATENATE(D29," - ",B29) -> MAFÊ - MED UNAERP
A30: 29 | B30: MED UNAERP | D30: ANA MATTOS | F30: ANALUISAGMATTOS | G30: 5 | H30: =CONCATENATE(D30," - ",B30) -> ANA MATTOS - MED UNAERP
A31: 30 | B31: MED UNAERP | D31: ANA FARIA | F31: ANALUQSF | G31: 38 | H31: =CONCATENATE(D31," - ",B31) -> ANA FARIA - MED UNAERP
A32: 31 | B32: MED UNAERP | D32: BIA | F32: BIAPRIMOA | G32: 32 | H32: =CONCATENATE(D32," - ",B32) -> BIA - MED UNAERP
A33: 32 | B33: MED UNAERP | D33: BRUNNA | F33: BRUNNATERRA | G33: 14 | H33: =CONCATENATE(D33," - ",B33) -> BRUNNA - MED UNAERP
A34: 33 | B34: MED UNAERP | D34: ISA | F34: ISAH_R_BORGES | G34: 31 | H34: =CONCATENATE(D34," - ",B34) -> ISA - MED UNAERP
A35: 34 | B35: MED UNAERP | D35: TEREZA | G35: 6 | H35: =CONCATENATE(D35," - ",B35) -> TEREZA - MED UNAERP
A36: 35 | B36: MED UNAERP | D36: GALVÃO | F36: M_GALVAOO | G36: 22 | H36: =CONCATENATE(D36," - ",B36) -> GALVÃO - MED UNAERP
A37: 36 | B37: MED UNAERP | D37: RAÍSSA | F37: RA_LOBO | G37: 40 | H37: =CONCATENATE(D37," - ",B37) -> RAÍSSA - MED UNAERP
A38: 37 | B38: MED UNAERP | D38: ANINHA | G38: 24 | H38: =CONCATENATE(D38," - ",B38) -> ANINHA - MED UNAERP
A39: 38 | B39: MED UNAERP | D39: MAYRA | G39: 20 | H39: =CONCATENATE(D39," - ",B39) -> MAYRA - MED UNAERP
A40: 39 | B40: MED UNAERP | D40: GIULIA

Sheet 2K25 ELITE LEAGUE
A1: CÉLULA | B1: APELIDO | C1: NÚMERO | D1: EQUIPE | E1: JOGOS | F1: PONTOS | G1: PPG | H1: FGM | I1: FGA | J1: %FG | K1: 2PM | L1: 2PA | M1: %2P | N1: 3PM | O1: 3PA | P1: %3P | Q1: FTM | R1: FTA | S1: %FT | T1: REB O | U1: REB D | V1: TOTAL REB | W1: # RPG | X1: AST | Y1: #APG | Z1: ERROS | AA1: ROUB | AB1: TOCOS | AC1: FALTAS C | AD1: FALTAS S | AE1: PLUS/MINUS | AF1: EFICIÊNCIA
A2: 1 | B2: LOBA | D2: LUS USP RP | E2: =COUNTIF('ESTATÍSTICAS ATLETAS'!I:I,B2) -> 4 | F2: =SUMIF('ESTATÍSTICAS ATLETAS'!I:I,B2,'ESTATÍSTICAS ATLETAS'!M:M) -> 2 | G2: =F2/E2 -> 0.5 | H2: =SUMIF('ESTATÍSTICAS ATLETAS'!$I:$I,$B2,'ESTATÍSTICAS ATLETAS'!N:N) -> 1 | I2: =SUMIF('ESTATÍSTICAS ATLETAS'!$I:$I,$B2,'ESTATÍSTICAS ATLETAS'!O:O) -> 18 | J2: =IFERROR(H2/I2,"") -> 0.055555556 | K2: =SUMIF('ESTATÍSTICAS ATLETAS'!$I:$I,$B2,'ESTATÍSTICAS ATLETAS'!Q:Q) -> 1 | L2: =SUMIF('ESTATÍSTICAS ATLETAS'!$I:$I,$B2,'ESTATÍSTICAS ATLETAS'!R:R) -> 18 | M2: =IFERROR(K2/L2,"") -> 0.055555556 | N2: =SUMIF('ESTATÍSTICAS ATLETAS'!$I:$I,$B2,'ESTATÍSTICAS ATLETAS'!T:T) -> 0 | O2: =SUMIF('ESTATÍSTICAS ATLETAS'!$I:$I,$B2,'ESTATÍSTICAS ATLETAS'!U:U) -> 0 | P2: =IFERROR(N2/O2,"") | Q2: =SUMIF('ESTATÍSTICAS ATLETAS'!$I:$I,$B2,'ESTATÍSTICAS ATLETAS'!W:W) -> 0 | R2: =SUMIF('ESTATÍSTICAS ATLETAS'!$I:$I,$B2,'ESTATÍSTICAS ATLETAS'!X:X) -> 0 | S2: =IFERROR(Q2/R2,"") | T2: =SUMIF('ESTATÍSTICAS ATLETAS'!$I:$I,$B2,'ESTATÍSTICAS ATLETAS'!Z:Z) -> 6 | U2: =SUMIF('ESTATÍSTICAS ATLETAS'!$I:$I,$B2,'ESTATÍSTICAS ATLETAS'!AA:AA) -> 7 | V2: =SUMIF('ESTATÍSTICAS ATLETAS'!$I:$I,$B2,'ESTATÍSTICAS ATLETAS'!AB:AB) -> 13 | W2: =V2/E2 -> 3.25 | X2: =SUMIF('ESTATÍSTICAS ATLETAS'!$I:$I,$B2,'ESTATÍSTICAS ATLETAS'!AC:AC) -> 1 | Y2: =X2/E2 -> 0.25 | Z2: =SUMIF('ESTATÍSTICAS ATLETAS'!$I:$I,$B2,'ESTATÍSTICAS ATLETAS'!AD:AD) -> 13 | AA2: =SUMIF('ESTATÍSTICAS ATLETAS'!$I:$I,$B2,'ESTATÍSTICAS ATLETAS'!AE:AE) -> 6 | AB2: =SUMIF('ESTATÍSTICAS ATLETAS'!$I:$I,$B2,'ESTATÍSTICAS ATLETAS'!AF:AF) -> 3 | AC2: =SUMIF('ESTATÍSTICAS ATLETAS'!$I:$I,$B2,'ESTATÍSTICAS ATLETAS'!AG:AG) -> 5 | AD2: =SUMIF('ESTATÍSTICAS ATLETAS'!$I:$I,$B2,'ESTATÍSTICAS ATLETAS'!AH:AH) -> 0 | AE2: =SUMIF('ESTATÍSTICAS ATLETAS'!$I:$I,$B2,'ESTATÍSTICAS ATLETAS'!AI:AI) -> -1 | AF2: =SUMIF('ESTATÍSTICAS ATLETAS'!$I:$I,$B2,'ESTATÍSTICAS ATLETAS'!AJ:AJ) -> -5
A3: 2 | B3: CHARLIE | D3: LUS USP RP | E3: =COUNTIF('ESTATÍSTICAS ATLETAS'!I:I,B3) -> 3 | F3: =SUMIF('ESTATÍSTICAS ATLETAS'!I:I,B3,'ESTATÍSTICAS ATLETAS'!M:M) -> 0 | G3: =F3/E3 -> 0 | H3: =SUMIF('ESTATÍSTICAS ATLETAS'!$I:$I,$B3,'ESTATÍSTICAS ATLETAS'!N:N) -> 0 | I3: =SUMIF('ESTATÍSTICAS ATLETAS'!$I:$I,$B3,'ESTATÍSTICAS ATLETAS'!O:O) -> 14 | J3: =IFERROR(H3/I3,"") -> 0 | K3: =SUMIF('ESTATÍSTICAS ATLETAS'!$I:$I,$B3,'ESTATÍSTICAS ATLETAS'!Q:Q) -> 0 | L3: =SUMIF('ESTATÍSTICAS ATLETAS'!$I:$I,$B3,'ESTATÍSTICAS ATLETAS'!R:R) -> 14 | M3: =IFERROR(K3/L3,"") -> 0 | N3: =SUMIF('ESTATÍSTICAS ATLETAS'!$I:$I,$B3,'ESTATÍSTICAS ATLETAS'!T:T) -> 0 | O3: =SUMIF('ESTATÍSTICAS ATLETAS'!$I:$I,$B3,'ESTATÍSTICAS ATLETAS'!U:U) -> 0 | P3: =IFERROR(N3/O3,"") | Q3: =SUMIF('ESTATÍSTICAS ATLETAS'!$I:$I,$B3,'ESTATÍSTICAS ATLETAS'!W:W) -> 0 | R3: =SUMIF('ESTATÍSTICAS ATLETAS'!$I:$I,$B3,'ESTATÍSTICAS ATLETAS'!X:X) -> 0 | S3: =IFERROR(Q3/R3,"") | T3: =SUMIF('ESTATÍSTICAS ATLETAS'!$I:$I,$B3,'ESTATÍSTICAS ATLETAS'!Z:Z) -> 6 | U3: =SUMIF('ESTATÍSTICAS ATLETAS'!$I:$I,$B3,'ESTATÍSTICAS ATLETAS'!AA:AA) -> 6 | V3: =SUMIF('ESTATÍSTICAS ATLETAS'!$I:$I,$B3,'ESTATÍSTICAS ATLETAS'!AB:AB) -> 12 | W3: =V3/E3 -> 4 | X3: =SUMIF('ESTATÍSTICAS ATLETAS'!$I:$I,$B3,'ESTATÍSTICAS ATLETAS'!AC:AC) -> 1 | Y3: =X3/E3 -> 0.33333333 | Z3: =SUMIF('ESTATÍSTICAS ATLETAS'!$I:$I,$B3,'ESTATÍSTICAS ATLETAS'!AD:AD) -> 6 | AA3: =SUMIF('ESTATÍSTICAS ATLETAS'!$I:$I,$B3,'ESTATÍSTICAS ATLETAS'!AE:AE) -> 1 | AB3: =SUMIF('ESTATÍSTICAS ATLETAS'!$I:$I,$B3,'ESTATÍSTICAS ATLETAS'!AF:AF) -> 0 | AC3: =SUMIF('ESTATÍSTICAS ATLETAS'!$I:$I,$B3,'ESTATÍSTICAS ATLETAS'!AG:AG) -> 3 | AD3: =SUMIF('ESTATÍSTICAS ATLETAS'!$I:$I,$B3,'ESTATÍSTICAS ATLETAS'!AH:AH) -> 0 | AE3: =SUMIF('ESTATÍSTICAS ATLETAS'!$I:$I,$B3,'ESTATÍSTICAS ATLETAS'!AI:AI) -> -10 | AF3: =SUMIF('ESTATÍSTICAS ATLETAS'!$I:$I,$B3,'ESTATÍSTICAS ATLETAS'!AJ:AJ) -> -6
A4: 3 | B4: PICK | D4: LUS USP RP | E4: =COUNTIF('ESTATÍSTICAS ATLETAS'!I:I,B4) -> 2 | F4: =SUMIF('ESTATÍSTICAS ATLETAS'!I:I,B4,'ESTATÍSTICAS ATLETAS'!M:M) -> 2 | G4: =F4/E4 -> 1 | H4: =SUMIF('ESTATÍSTICAS ATLETAS'!$I:$I,$B4,'ESTATÍSTICAS ATLETAS'!N:N) -> 1 | I4: =SUMIF('ESTATÍSTICAS ATLETAS'!$I:$I,$B4,'ESTATÍSTICAS ATLETAS'!O:O) -> 3 | J4: =IFERROR(H4/I4,"") -> 0.33333333 | K4: =SUMIF('ESTATÍSTICAS ATLETAS'!$I:$I,$B4,'ESTATÍSTICAS ATLETAS'!Q:Q) -> 1 | L4: =SUMIF('ESTATÍSTICAS ATLETAS'!$I:$I,$B4,'ESTATÍSTICAS ATLETAS'!R:R) -> 3 | M4: =IFERROR(K4/L4,"") -> 0.33333333 | N4: =SUMIF('ESTATÍSTICAS ATLETAS'!$I:$I,$B4,'ESTATÍSTICAS ATLETAS'!T:T) -> 0 | O4: =SUMIF('ESTATÍSTICAS ATLETAS'!$I:$I,$B4,'ESTATÍSTICAS ATLETAS'!U:U) -> 0 | P4: =IFERROR(N4/O4,"") | Q4: =SUMIF('ESTATÍSTICAS ATLETAS'!$I:$I,$B4,'ESTATÍSTICAS ATLETAS'!W:W) -> 0 | R4: =SUMIF('ESTATÍSTICAS ATLETAS'!$I:$I,$B4,'ESTATÍSTICAS ATLETAS'!X:X) -> 0 | S4: =IFERROR(Q4/R4,"") | T4: =SUMIF('ESTATÍSTICAS ATLETAS'!$I:$I,$B4,'ESTATÍSTICAS ATLETAS'!Z:Z) -> 3 | U4: =SUMIF('ESTATÍSTICAS ATLETAS'!$I:$I,$B4,'ESTATÍSTICAS ATLETAS'!AA:AA) -> 1 | V4: =SUMIF('ESTATÍSTICAS ATLETAS'!$I:$I,$B4,'ESTATÍSTICAS ATLETAS'!AB:AB) -> 4 | W4: =V4/E4 -> 2 | X4: =SUMIF('ESTATÍSTICAS ATLETAS'!$I:$I,$B4,'ESTATÍSTICAS ATLETAS'!AC:AC) -> 2 | Y4: =X4/E4 -> 1 | Z4: =SUMIF('ESTATÍSTICAS ATLETAS'!$I:$I,$B4,'ESTATÍSTICAS ATLETAS'!AD:AD) -> 5 | AA4: =SUMIF('ESTATÍSTICAS ATLETAS'!$I:$I,$B4,'ESTATÍSTICAS ATLETAS'!AE:AE) -> 2 | AB4: =SUMIF('ESTATÍSTICAS ATLETAS'!$I:$I,$B4,'ESTATÍSTICAS ATLETAS'!AF:AF) -> 0 | AC4: =SUMIF('ESTATÍSTICAS ATLETAS'!$I:$I,$B4,'ESTATÍSTICAS ATLETAS'!AG:AG) -> 2 | AD4: =SUMIF('ESTATÍSTICAS ATLETAS'!$I:$I,$B4,'ESTATÍSTICAS ATLETAS'!AH:AH) -> 0 | AE4: =SUMIF('ESTATÍSTICAS ATLETAS'!$I:$I,$B4,'ESTATÍSTICAS ATLETAS'!AI:AI) -> -10 | AF4: =SUMIF('ESTATÍSTICAS ATLETAS'!$I:$I,$B4,'ESTATÍSTICAS ATLETAS'!AJ:AJ) -> 3
A5: 4 | B5: ELÉTRICA | D5: LUS USP RP | E5: =COUNTIF('ESTATÍSTICAS ATLETAS'!I:I,B5) -> 2 | F5: =SUMIF('ESTATÍSTICAS ATLETAS'!I:I,B5,'ESTATÍSTICAS ATLETAS'!M:M) -> 0 | G5: =F5/E5 -> 0 | H5: =SUMIF('ESTATÍSTICAS ATLETAS'!$I:$I,$B5,'ESTATÍSTICAS ATLETAS'!N:N) -> 0 | I5: =SUMIF('ESTATÍSTICAS ATLETAS'!$I:$I,$B5,'ESTATÍSTICAS ATLETAS'!O:O) -> 2 | J5: =IFERROR(H5/I5,"") -> 0 | K5: =SUMIF('ESTATÍSTICAS ATLETAS'!$I:$I,$B5,'ESTATÍSTICAS ATLETAS'!Q:Q) -> 0 | L5: =SUMIF('ESTATÍSTICAS ATLETAS'!$I:$I,$B5,'ESTATÍSTICAS ATLETAS'!R:R) -> 1 | M5: =IFERROR(K5/L5,"") -> 0 | N5: =SUMIF('ESTATÍSTICAS ATLETAS'!$I:$I,$B5,'ESTATÍSTICAS ATLETAS'!T:T) -> 0 | O5: =SUMIF('ESTATÍSTICAS ATLETAS'!$I:$I,$B5,'ESTATÍSTICAS ATLETAS'!U:U) -> 1 | P5: =IFERROR(N5/O5,"") -> 0 | Q5: =SUMIF('ESTATÍSTICAS ATLETAS'!$I:$I,$B5,'ESTATÍSTICAS ATLETAS'!W:W) -> 0 | R5: =SUMIF('ESTATÍSTICAS ATLETAS'!$I:$I,$B5,'ESTATÍSTICAS ATLETAS'!X:X) -> 0 | S5: =IFERROR(Q5/R5,"") | T5: =SUMIF('ESTATÍSTICAS ATLETAS'!$I:$I,$B5,'ESTATÍSTICAS ATLETAS'!Z:Z) -> 0 | U5: =SUMIF('ESTATÍSTICAS ATLETAS'!$I:$I,$B5,'ESTATÍSTICAS ATLETAS'!AA:AA) -> 0 | V5: =SUMIF('ESTATÍSTICAS ATLETAS'!$I:$I,$B5,'ESTATÍSTICAS ATLETAS'!AB:AB) -> 0 | W5: =V5/E5 -> 0 | X5: =SUMIF('ESTATÍSTICAS ATLETAS'!$I:$I,$B5,'ESTATÍSTICAS ATLETAS'!AC:AC) -> 0 | Y5: =X5/E5 -> 0 | Z5: =SUMIF('ESTATÍSTICAS ATLETAS'!$I:$I,$B5,'ESTATÍSTICAS ATLETAS'!AD:AD) -> 2 | AA5: =SUMIF('ESTATÍSTICAS ATLETAS'!$I:$I,$B5,'ESTATÍSTICAS ATLETAS'!AE:AE) -> 0 | AB5: =SUMIF('ESTATÍSTICAS ATLETAS'!$I:$I,$B5,'ESTATÍSTICAS ATLETAS'!AF:AF) -> 0 | AC5: =SUMIF('ESTATÍSTICAS ATLETAS'!$I:$I,$B5,'ESTATÍSTICAS ATLETAS'!AG:AG) -> 1 | AD5: =SUMIF('ESTATÍSTICAS ATLETAS'!$I:$I,$B5,'ESTATÍSTICAS ATLETAS'!AH:AH) -> 0 | AE5: =SUMIF('ESTATÍSTICAS ATLETAS'!$I:$I,$B5,'ESTATÍSTICAS ATLETAS'!AI:AI) -> 6 | AF5: =SUMIF('ESTATÍSTICAS ATLETAS'!$I:$I,$B5,'ESTATÍSTICAS ATLETAS'!AJ:AJ) -> -4
A6: 5 | B6: DANONE | D6: LUS USP RP | E6: =COUNTIF('ESTATÍSTICAS ATLETAS'!I:I,B6) -> 1 | F6: =SUMIF('ESTATÍSTICAS ATLETAS'!I:I,B6,'ESTATÍSTICAS ATLETAS'!M:M) -> 0 | G6: =F6/E6 -> 0 | H6: =SUMIF('ESTATÍSTICAS ATLETAS'!$I:$I,$B6,'ESTATÍSTICAS ATLETAS'!N:N) -> 0 | I6: =SUMIF('ESTATÍSTICAS ATLETAS'!$I:$I,$B6,'ESTATÍSTICAS ATLETAS'!O:O) -> 0 | J6: =IFERROR(H6/I6,"") | K6: =SUMIF('ESTATÍSTICAS ATLETAS'!$I:$I,$B6,'ESTATÍSTICAS ATLETAS'!Q:Q) -> 0 | L6: =SUMIF('ESTATÍSTICAS ATLETAS'!$I:$I,$B6,'ESTATÍSTICAS ATLETAS'!R:R) -> 0 | M6: =IFERROR(K6/L6,"") | N6: =SUMIF('ESTATÍSTICAS ATLETAS'!$I:$I,$B6,'ESTATÍSTICAS ATLETAS'!T:T) -> 0 | O6: =SUMIF('ESTATÍSTICAS ATLETAS'!$I:$I,$B6,'ESTATÍSTICAS ATLETAS'!U:U) -> 0 | P6: =IFERROR(N6/O6,"") | Q6: =SUMIF('ESTATÍSTICAS ATLETAS'!$I:$I,$B6,'ESTATÍSTICAS ATLETAS'!W:W) -> 0 | R6: =SUMIF('ESTATÍSTICAS ATLETAS'!$I:$I,$B6,'ESTATÍSTICAS ATLETAS'!X:X) -> 0 | S6: =IFERROR(Q6/R6,"") | T6: =SUMIF('ESTATÍSTICAS ATLETAS'!$I:$I,$B6,'ESTATÍSTICAS ATLETAS'!Z:Z) -> 0 | U6: =SUMIF('ESTATÍSTICAS ATLETAS'!$I:$I,$B6,'ESTATÍSTICAS ATLETAS'!AA:AA) -> 2 | V6: =SUMIF('ESTATÍSTICAS ATLETAS'!$I:$I,$B6,'ESTATÍSTICAS ATLETAS'!AB:AB) -> 2 | W6: =V6/E6 -> 2 | X6: =SUMIF('ESTATÍSTICAS ATLETAS'!$I:$I,$B6,'ESTATÍSTICAS ATLETAS'!AC:AC) -> 0 | Y6: =X6/E6 -> 0 | Z6: =SUMIF('ESTATÍSTICAS ATLETAS'!$I:$I,$B6,'ESTATÍSTICAS ATLETAS'!AD:AD) -> 2 | AA6: =SUMIF('ESTATÍSTICAS ATLETAS'!$I:$I,$B6,'ESTATÍSTICAS ATLETAS'!AE:AE) -> 0 | AB6: =SUMIF('ESTATÍSTICAS ATLETAS'!$I:$I,$B6,'ESTATÍSTICAS ATLETAS'!AF:AF) -> 0 | AC6: =SUMIF('ESTATÍSTICAS ATLETAS'!$I:$I,$B6,'ESTATÍSTICAS ATLETAS'!AG:AG) -> 1 | AD6: =SUMIF('ESTATÍSTICAS ATLETAS'!$I:$I,$B6,'ESTATÍSTICAS ATLETAS'!AH:AH) -> 1 | AE6: =SUMIF('ESTATÍSTICAS ATLETAS'!$I:$I,$B6,'ESTATÍSTICAS ATLETAS'!AI:AI) -> 0 | AF6: =SUMIF('ESTATÍSTICAS ATLETAS'!$I:$I,$B6,'ESTATÍSTICAS ATLETAS'!AJ:AJ) -> 0
A7: 6 | B7: XANDRITA | D7: LUS USP RP | E7: =COUNTIF('ESTATÍSTICAS ATLETAS'!I:I,B7) -> 4 | F7: =SUMIF('ESTATÍSTICAS ATLETAS'!I:I,B7,'ESTATÍSTICAS ATLETAS'!M:M) -> 17 | G7: =F7/E7 -> 4.25 | H7: =SUMIF('ESTATÍSTICAS ATLETAS'!$I:$I,$B7,'ESTATÍSTICAS ATLETAS'!N:N) -> 8 | I7: =SUMIF('ESTATÍSTICAS ATLETAS'!$I:$I,$B7,'ESTATÍSTICAS ATLETAS'!O:O) -> 97 | J7: =IFERROR(H7/I7,"") -> 0.082474227 | K7: =SUMIF('ESTATÍSTICAS ATLETAS'!$I:$I,$B7,'ESTATÍSTICAS ATLETAS'!Q:Q) -> 8 | L7: =SUMIF('ESTATÍSTICAS ATLETAS'!$I:$I,$B7,'ESTATÍSTICAS ATLETAS'!R:R) -> 90 | M7: =IFERROR(K7/L7,"") -> 0.088888889 | N7: =SUMIF('ESTATÍSTICAS ATLETAS'!$I:$I,$B7,'ESTATÍSTICAS ATLETAS'!T:T) -> 0 | O7: =SUMIF('ESTATÍSTICAS ATLETAS'!$I:$I,$B7,'ESTATÍSTICAS ATLETAS'!U:U) -> 7 | P7: =IFERROR(N7/O7,"") -> 0 | Q7: =SUMIF('ESTATÍSTICAS ATLETAS'!$I:$I,$B7,'ESTATÍSTICAS ATLETAS'!W:W) -> 1 | R7: =SUMIF('ESTATÍSTICAS ATLETAS'!$I:$I,$B7,'ESTATÍSTICAS ATLETAS'!X:X) -> 10 | S7: =IFERROR(Q7/R7,"") -> 0.1 | T7: =SUMIF('ESTATÍSTICAS ATLETAS'!$I:$I,$B7,'ESTATÍSTICAS ATLETAS'!Z:Z) -> 22 | U7: =SUMIF('ESTATÍSTICAS ATLETAS'!$I:$I,$B7,'ESTATÍSTICAS ATLETAS'!AA:AA) -> 20 | V7: =SUMIF('ESTATÍSTICAS ATLETAS'!$I:$I,$B7,'ESTATÍSTICAS ATLETAS'!AB:AB) -> 42 | W7: =V7/E7 -> 10.5 | X7: =SUMIF('ESTATÍSTICAS ATLETAS'!$I:$I,$B7,'ESTATÍSTICAS ATLETAS'!AC:AC) -> 6 | Y7: =X7/E7 -> 1.5 | Z7: =SUMIF('ESTATÍSTICAS ATLETAS'!$I:$I,$B7,'ESTATÍSTICAS ATLETAS'!AD:AD) -> 13 | AA7: =SUMIF('ESTATÍSTICAS ATLETAS'!$I:$I,$B7,'ESTATÍSTICAS ATLETAS'!AE:AE) -> 25 | AB7: =SUMIF('ESTATÍSTICAS ATLETAS'!$I:$I,$B7,'ESTATÍSTICAS ATLETAS'!AF:AF) -> 3 | AC7: =SUMIF('ESTATÍSTICAS ATLETAS'!$I:$I,$B7,'ESTATÍSTICAS ATLETAS'!AG:AG) -> 7 | AD7: =SUMIF('ESTATÍSTICAS ATLETAS'!$I:$I,$B7,'ESTATÍSTICAS ATLETAS'!AH:AH) -> 11 | AE7: =SUMIF('ESTATÍSTICAS ATLETAS'!$I:$I,$B7,'ESTATÍSTICAS ATLETAS'!AI:AI) -> -9 | AF7: =SUMIF('ESTATÍSTICAS ATLETAS'!$I:$I,$B7,'ESTATÍSTICAS ATLETAS'!AJ:AJ) -> -18
A8: 7 | B8: BABY | D8: LUS USP RP | E8: =COUNTIF('ESTATÍSTICAS ATLETAS'!I:I,B8) -> 4 | F8: =SUMIF('ESTATÍSTICAS ATLETAS'!I:I,B8,'ESTATÍSTICAS ATLETAS'!M:M) -> 35 | G8: =F8/E8 -> 8.75 | H8: =SUMIF('ESTATÍSTICAS ATLETAS'!$I:$I,$B8,'ESTATÍSTICAS ATLETAS'!N:N) -> 14 | I8: =SUMIF('ESTATÍSTICAS ATLETAS'!$I:$I,$B8,'ESTATÍSTICAS ATLETAS'!O:O) -> 97 | J8: =IFERROR(H8/I8,"") -> 0.1443299 | K8: =SUMIF('ESTATÍSTICAS ATLETAS'!$I:$I,$B8,'ESTATÍSTICAS ATLETAS'!Q:Q) -> 12 | L8: =SUMIF('ESTATÍSTICAS ATLETAS'!$I:$I,$B8,'ESTATÍSTICAS ATLETAS'!R:R) -> 73 | M8: =IFERROR(K8/L8,"") -> 0.16438356 | N8: =SUMIF('ESTATÍSTICAS ATLETAS'!$I:$I,$B8,'ESTATÍSTICAS ATLETAS'!T:T) -> 2 | O8: =SUMIF('ESTATÍSTICAS ATLETAS'!$I:$I,$B8,'ESTATÍSTICAS ATLETAS'!U:U) -> 24 | P8: =IFERROR(N8/O8,"") -> 0.083333333 | Q8: =SUMIF('ESTATÍSTICAS ATLETAS'!$I:$I,$B8,'ESTATÍSTICAS ATLETAS'!W:W) -> 5 | R8: =SUMIF('ESTATÍSTICAS ATLETAS'!$I:$I,$B8,'ESTATÍSTICAS ATLETAS'!X:X) -> 21 | S8: =IFERROR(Q8/R8,"") -> 0.23809524 | T8: =SUMIF('ESTATÍSTICAS ATLETAS'!$I:$I,$B8,'ESTATÍSTICAS ATLETAS'!Z:Z) -> 30 | U8: =SUMIF('ESTATÍSTICAS ATLETAS'!$I:$I,$B8,'ESTATÍSTICAS ATLETAS'!AA:AA) -> 29 | V8: =SUMIF('ESTATÍSTICAS ATLETAS'!$I:$I,$B8,'ESTATÍSTICAS ATLETAS'!AB:AB) -> 59 | W8: =V8/E8 -> 14.75 | X8: =SUMIF('ESTATÍSTICAS ATLETAS'!$I:$I,$B8,'ESTATÍSTICAS ATLETAS'!AC:AC) -> 6 | Y8: =X8/E8 -> 1.5 | Z8: =SUMIF('ESTATÍSTICAS ATLETAS'!$I:$I,$B8,'ESTATÍSTICAS ATLETAS'!AD:AD) -> 22 | AA8: =SUMIF('ESTATÍSTICAS ATLETAS'!$I:$I,$B8,'ESTATÍSTICAS ATLETAS'!AE:AE) -> 27 | AB8: =SUMIF('ESTATÍSTICAS ATLETAS'!$I:$I,$B8,'ESTATÍSTICAS ATLETAS'!AF:AF) -> 6 | AC8: =SUMIF('ESTATÍSTICAS ATLETAS'!$I:$I,$B8,'ESTATÍSTICAS ATLETAS'!AG:AG) -> 16 | AD8: =SUMIF('ESTATÍSTICAS ATLETAS'!$I:$I,$B8,'ESTATÍSTICAS ATLETAS'!AH:AH) -> 16 | AE8: =SUMIF('ESTATÍSTICAS ATLETAS'!$I:$I,$B8,'ESTATÍSTICAS ATLETAS'!AI:AI) -> -6 | AF8: =SUMIF('ESTATÍSTICAS ATLETAS'!$I:$I,$B8,'ESTATÍSTICAS ATLETAS'!AJ:AJ) -> 12
A9: 8 | B9: SUFOCO | D9: LUS USP RP | E9: =COUNTIF('ESTATÍSTICAS ATLETAS'!I:I,B9) -> 2 | F9: =SUMIF('ESTATÍSTICAS ATLETAS'!I:I,B9,'ESTATÍSTICAS ATLETAS'!M:M) -> 10 | G9: =F9/E9 -> 5 | H9: =SUMIF('ESTATÍSTICAS ATLETAS'!$I:$I,$B9,'ESTATÍSTICAS ATLETAS'!N:N) -> 4 | I9: =SUMIF('ESTATÍSTICAS ATLETAS'!$I:$I,$B9,'ESTATÍSTICAS ATLETAS'!O:O) -> 28 | J9: =IFERROR(H9/I9,"") -> 0.14285714 | K9: =SUMIF('ESTATÍSTICAS ATLETAS'!$I:$I,$B9,'ESTATÍSTICAS ATLETAS'!Q:Q) -> 3 | L9: =SUMIF('ESTATÍSTICAS ATLETAS'!$I:$I,$B9,'ESTATÍSTICAS ATLETAS'!R:R) -> 18 | M9: =IFERROR(K9/L9,"") -> 0.16666667 | N9: =SUMIF('ESTATÍSTICAS ATLETAS'!$I:$I,$B9,'ESTATÍSTICAS ATLETAS'!T:T) -> 1 | O9: =SUMIF('ESTATÍSTICAS ATLETAS'!$I:$I,$B9,'ESTATÍSTICAS ATLETAS'!U:U) -> 10 | P9: =IFERROR(N9/O9,"") -> 0.1 | Q9: =SUMIF('ESTATÍSTICAS ATLETAS'!$I:$I,$B9,'ESTATÍSTICAS ATLETAS'!W:W) -> 1 | R9: =SUMIF('ESTATÍSTICAS ATLETAS'!$I:$I,$B9,'ESTATÍSTICAS ATLETAS'!X:X) -> 7 | S9: =IFERROR(Q9/R9,"") -> 0.14285714 | T9: =SUMIF('ESTATÍSTICAS ATLETAS'!$I:$I,$B9,'ESTATÍSTICAS ATLETAS'!Z:Z) -> 4 | U9: =SUMIF('ESTATÍSTICAS ATLETAS'!$I:$I,$B9,'ESTATÍSTICAS ATLETAS'!AA:AA) -> 10 | V9: =SUMIF('ESTATÍSTICAS ATLETAS'!$I:$I,$B9,'ESTATÍSTICAS ATLETAS'!AB:AB) -> 14 | W9: =V9/E9 -> 7 | X9: =SUMIF('ESTATÍSTICAS ATLETAS'!$I:$I,$B9,'ESTATÍSTICAS ATLETAS'!AC:AC) -> 4 | Y9: =X9/E9 -> 2 | Z9: =SUMIF('ESTATÍSTICAS ATLETAS'!$I:$I,$B9,'ESTATÍSTICAS ATLETAS'!AD:AD) -> 11 | AA9: =SUMIF('ESTATÍSTICAS ATLETAS'!$I:$I,$B9,'ESTATÍSTICAS ATLETAS'!AE:AE) -> 16 | AB9: =SUMIF('ESTATÍSTICAS ATLETAS'!$I:$I,$B9,'ESTATÍSTICAS ATLETAS'!AF:AF) -> 1 | AC9: =SUMIF('ESTATÍSTICAS ATLETAS'!$I:$I,$B9,'ESTATÍSTICAS ATLETAS'!AG:AG) -> 3 | AD9: =SUMIF('ESTATÍSTICAS ATLETAS'!$I:$I,$B9,'ESTATÍSTICAS ATLETAS'!AH:AH) -> 6 | AE9: =SUMIF('ESTATÍSTICAS ATLETAS'!$I:$I,$B9,'ESTATÍSTICAS ATLETAS'!AI:AI) -> -11 | AF9: =SUMIF('ESTATÍSTICAS ATLETAS'!$I:$I,$B9,'ESTATÍSTICAS ATLETAS'!AJ:AJ) -> 4
A10: 9 | B10: BANHO | D10: LUS USP RP | E10: =COUNTIF('ESTATÍSTICAS ATLETAS'!I:I,B10) -> 1 | F10: =SUMIF('ESTATÍSTICAS ATLETAS'!I:I,B10,'ESTATÍSTICAS ATLETAS'!M:M) -> 0 | G10: =F10/E10 -> 0 | H10: =SUMIF('ESTATÍSTICAS ATLETAS'!$I:$I,$B10,'ESTATÍSTICAS ATLETAS'!N:N) -> 0 | I10: =SUMIF('ESTATÍSTICAS ATLETAS'!$I:$I,$B10,'ESTATÍSTICAS ATLETAS'!O:O) -> 0 | J10: =IFERROR(H10/I10,"") | K10: =SUMIF('ESTATÍSTICAS ATLETAS'!$I:$I,$B10,'ESTATÍSTICAS ATLETAS'!Q:Q) -> 0 | L10: =SUMIF('ESTATÍSTICAS ATLETAS'!$I:$I,$B10,'ESTATÍSTICAS ATLETAS'!R:R) -> 0 | M10: =IFERROR(K10/L10,"") | N10: =SUMIF('ESTATÍSTICAS ATLETAS'!$I:$I,$B10,'ESTATÍSTICAS ATLETAS'!T:T) -> 0 | O10: =SUMIF('ESTATÍSTICAS ATLETAS'!$I:$I,$B10,'ESTATÍSTICAS ATLETAS'!U:U) -> 0 | P10: =IFERROR(N10/O10,"") | Q10: =SUMIF('ESTATÍSTICAS ATLETAS'!$I:$I,$B10,'ESTATÍSTICAS ATLETAS'!W:W) -> 0 | R10: =SUMIF('ESTATÍSTICAS ATLETAS'!$I:$I,$B10,'ESTATÍSTICAS ATLETAS'!X:X) -> 0 | S10: =IFERROR(Q10/R10,"") | T10: =SUMIF('ESTATÍSTICAS ATLETAS'!$I:$I,$B10,'ESTATÍSTICAS ATLETAS'!Z:Z) -> 0 | U10: =SUMIF('ESTATÍSTICAS ATLETAS'!$I:$I,$B10,'ESTATÍSTICAS ATLETAS'!AA:AA) -> 0 | V10: =SUMIF('ESTATÍSTICAS ATLETAS'!$I:$I,$B10,'ESTATÍSTICAS ATLETAS'!AB:AB) -> 0 | W10: =V10/E10 -> 0 | X10: =SUMIF('ESTATÍSTICAS ATLETAS'!$I:$I,$B10,'ESTATÍSTICAS ATLETAS'!AC:AC) -> 0 | Y10: =X10/E10 -> 0 | Z10: =SUMIF('ESTATÍSTICAS ATLETAS'!$I:$I,$B10,'ESTATÍSTICAS ATLETAS'!AD:AD) -> 0 | AA10: =SUMIF('ESTATÍSTICAS ATLETAS'!$I:$I,$B10,'ESTATÍSTICAS ATLETAS'!AE:AE) -> 0 | AB10: =SUMIF('ESTATÍSTICAS ATLETAS'!$I:$I,$B10,'ESTATÍSTICAS ATLETAS'!AF:AF) -> 0 | AC10: =SUMIF('ESTATÍSTICAS ATLETAS'!$I:$I,$B10,'ESTATÍSTICAS ATLETAS'!AG:AG) -> 0 | AD10: =SUMIF('ESTATÍSTICAS ATLETAS'!$I:$I,$B10,'ESTATÍSTICAS ATLETAS'!AH:AH) -> 0 | AE10: =SUMIF('ESTATÍSTICAS ATLETAS'!$I:$I,$B10,'ESTATÍSTICAS ATLETAS'!AI:AI) -> -2 | AF10: =SUMIF('ESTATÍSTICAS ATLETAS'!$I:$I,$B10,'ESTATÍSTICAS ATLETAS'!AJ:AJ) -> 0
A11: 10 | B11: MABS | D11: LUS USP RP | E11: =COUNTIF('ESTATÍSTICAS ATLETAS'!I:I,B11) -> 2 | F11: =SUMIF('ESTATÍSTICAS ATLETAS'!I:I,B11,'ESTATÍSTICAS ATLETAS'!M:M) -> 0 | G11: =F11/E11 -> 0 | H11: =SUMIF('ESTATÍSTICAS ATLETAS'!$I:$I,$B11,'ESTATÍSTICAS ATLETAS'!N:N) -> 0 | I11: =SUMIF('ESTATÍSTICAS ATLETAS'!$I:$I,$B11,'ESTATÍSTICAS ATLETAS'!O:O) -> 1 | J11: =IFERROR(H11/I11,"") -> 0 | K11: =SUMIF('ESTATÍSTICAS ATLETAS'!$I:$I,$B11,'ESTATÍSTICAS ATLETAS'!Q:Q) -> 0 | L11: =SUMIF('ESTATÍSTICAS ATLETAS'!$I:$I,$B11,'ESTATÍSTICAS ATLETAS'!R:R) -> 1 | M11: =IFERROR(K11/L11,"") -> 0 | N11: =SUMIF('ESTATÍSTICAS ATLETAS'!$I:$I,$B11,'ESTATÍSTICAS ATLETAS'!T:T) -> 0 | O11: =SUMIF('ESTATÍSTICAS ATLETAS'!$I:$I,$B11,'ESTATÍSTICAS ATLETAS'!U:U) -> 0 | P11: =IFERROR(N11/O11,"") | Q11: =SUMIF('ESTATÍSTICAS ATLETAS'!$I:$I,$B11,'ESTATÍSTICAS ATLETAS'!W:W) -> 0 | R11: =SUMIF('ESTATÍSTICAS ATLETAS'!$I:$I,$B11,'ESTATÍSTICAS ATLETAS'!X:X) -> 0 | S11: =IFERROR(Q11/R11,"") | T11: =SUMIF('ESTATÍSTICAS ATLETAS'!$I:$I,$B11,'ESTATÍSTICAS ATLETAS'!Z:Z) -> 1 | U11: =SUMIF('ESTATÍSTICAS ATLETAS'!$I:$I,$B11,'ESTATÍSTICAS ATLETAS'!AA:AA) -> 1 | V11: =SUMIF('ESTATÍSTICAS ATLETAS'!$I:$I,$B11,'ESTATÍSTICAS ATLETAS'!AB:AB) -> 2 | W11: =V11/E11 -> 1 | X11: =SUMIF('ESTATÍSTICAS ATLETAS'!$I:$I,$B11,'ESTATÍSTICAS ATLETAS'!AC:AC) -> 0 | Y11: =X11/E11 -> 0 | Z11: =SUMIF('ESTATÍSTICAS ATLETAS'!$I:$I,$B11,'ESTATÍSTICAS ATLETAS'!AD:AD) -> 0 | AA11: =SUMIF('ESTATÍSTICAS ATLETAS'!$I:$I,$B11,'ESTATÍSTICAS ATLETAS'!AE:AE) -> 0 | AB11: =SUMIF('ESTATÍSTICAS ATLETAS'!$I:$I,$B11,'ESTATÍSTICAS ATLETAS'!AF:AF) -> 0 | AC11: =SUMIF('ESTATÍSTICAS ATLETAS'!$I:$I,$B11,'ESTATÍSTICAS ATLETAS'!AG:AG) -> 1 | AD11: =SUMIF('ESTATÍSTICAS ATLETAS'!$I:$I,$B11,'ESTATÍSTICAS ATLETAS'!AH:AH) -> 0 | AE11: =SUMIF('ESTATÍSTICAS ATLETAS'!$I:$I,$B11,'ESTATÍSTICAS ATLETAS'!AI:AI) -> 3 | AF11: =SUMIF('ESTATÍSTICAS ATLETAS'!$I:$I,$B11,'ESTATÍSTICAS ATLETAS'!AJ:AJ) -> 1
A12: 11 | B12: MARIÊ | D12: LUS USP RP | E12: =COUNTIF('ESTATÍSTICAS ATLETAS'!I:I,B12) -> 3 | F12: =SUMIF('ESTATÍSTICAS ATLETAS'!I:I,B12,'ESTATÍSTICAS ATLETAS'!M:M) -> 0 | G12: =F12/E12 -> 0 | H12: =SUMIF('ESTATÍSTICAS ATLETAS'!$I:$I,$B12,'ESTATÍSTICAS ATLETAS'!N:N) -> 0 | I12: =SUMIF('ESTATÍSTICAS ATLETAS'!$I:$I,$B12,'ESTATÍSTICAS ATLETAS'!O:O) -> 1 | J12: =IFERROR(H12/I12,"") -> 0 | K12: =SUMIF('ESTATÍSTICAS ATLETAS'!$I:$I,$B12,'ESTATÍSTICAS ATLETAS'!Q:Q) -> 0 | L12: =SUMIF('ESTATÍSTICAS ATLETAS'!$I:$I,$B12,'ESTATÍSTICAS ATLETAS'!R:R) -> 1 | M12: =IFERROR(K12/L12,"") -> 0 | N12: =SUMIF('ESTATÍSTICAS ATLETAS'!$I:$I,$B12,'ESTATÍSTICAS ATLETAS'!T:T) -> 0 | O12: =SUMIF('ESTATÍSTICAS ATLETAS'!$I:$I,$B12,'ESTATÍSTICAS ATLETAS'!U:U) -> 0 | P12: =IFERROR(N12/O12,"") | Q12: =SUMIF('ESTATÍSTICAS ATLETAS'!$I:$I,$B12,'ESTATÍSTICAS ATLETAS'!W:W) -> 0 | R12: =SUMIF('ESTATÍSTICAS ATLETAS'!$I:$I,$B12,'ESTATÍSTICAS ATLETAS'!X:X) -> 0 | S12: =IFERROR(Q12/R12,"") | T12: =SUMIF('ESTATÍSTICAS ATLETAS'!$I:$I,$B12,'ESTATÍSTICAS ATLETAS'!Z:Z) -> 0 | U12: =SUMIF('ESTATÍSTICAS ATLETAS'!$I:$I,$B12,'ESTATÍSTICAS ATLETAS'!AA:AA) -> 1 | V12: =SUMIF('ESTATÍSTICAS ATLETAS'!$I:$I,$B12,'ESTATÍSTICAS ATLETAS'!AB:AB) -> 1 | W12: =V12/E12 -> 0.33333333 | X12: =SUMIF('ESTATÍSTICAS ATLETAS'!$I:$I,$B12,'ESTATÍSTICAS ATLETAS'!AC:AC) -> 0 | Y12: =X12/E12 -> 0 | Z12: =SUMIF('ESTATÍSTICAS ATLETAS'!$I:$I,$B12,'ESTATÍSTICAS ATLETAS'!AD:AD) -> 2 | AA12: =SUMIF('ESTATÍSTICAS ATLETAS'!$I:$I,$B12,'ESTATÍSTICAS ATLETAS'!AE:AE) -> 0 | AB12: =SUMIF('ESTATÍSTICAS ATLETAS'!$I:$I,$B12,'ESTATÍSTICAS ATLETAS'!AF:AF) -> 0 | AC12: =SUMIF('ESTATÍSTICAS ATLETAS'!$I:$I,$B12,'ESTATÍSTICAS ATLETAS'!AG:AG) -> 1 | AD12: =SUMIF('ESTATÍSTICAS ATLETAS'!$I:$I,$B12,'ESTATÍSTICAS ATLETAS'!AH:AH) -> 0 | AE12: =SUMIF('ESTATÍSTICAS ATLETAS'!$I:$I,$B12,'ESTATÍSTICAS ATLETAS'!AI:AI) -> 0 | AF12: =SUMIF('ESTATÍSTICAS ATLETAS'!$I:$I,$B12,'ESTATÍSTICAS ATLETAS'!AJ:AJ) -> -2
A13: 12 | B13: PURURUCA | D13: LUS USP RP | E13: =COUNTIF('ESTATÍSTICAS ATLETAS'!I:I,B13) -> 2 | F13: =SUMIF('ESTATÍSTICAS ATLETAS'!I:I,B13,'ESTATÍSTICAS ATLETAS'!M:M) -> 2 | G13: =F13/E13 -> 1 | H13: =SUMIF('ESTATÍSTICAS ATLETAS'!$I:$I,$B13,'ESTATÍSTICAS ATLETAS'!N:N) -> 1 | I13: =SUMIF('ESTATÍSTICAS ATLETAS'!$I:$I,$B13,'ESTATÍSTICAS ATLETAS'!O:O) -> 10 | J13: =IFERROR(H13/I13,"") -> 0.1 | K13: =SUMIF('ESTATÍSTICAS ATLETAS'!$I:$I,$B13,'ESTATÍSTICAS ATLETAS'!Q:Q) -> 1 | L13: =SUMIF('ESTATÍSTICAS ATLETAS'!$I:$I,$B13,'ESTATÍSTICAS ATLETAS'!R:R) -> 10 | M13: =IFERROR(K13/L13,"") -> 0.1 | N13: =SUMIF('ESTATÍSTICAS ATLETAS'!$I:$I,$B13,'ESTATÍSTICAS ATLETAS'!T:T) -> 0 | O13: =SUMIF('ESTATÍSTICAS ATLETAS'!$I:$I,$B13,'ESTATÍSTICAS ATLETAS'!U:U) -> 0 | P13: =IFERROR(N13/O13,"") | Q13: =SUMIF('ESTATÍSTICAS ATLETAS'!$I:$I,$B13,'ESTATÍSTICAS ATLETAS'!W:W) -> 0 | R13: =SUMIF('ESTATÍSTICAS ATLETAS'!$I:$I,$B13,'ESTATÍSTICAS ATLETAS'!X:X) -> 4 | S13: =IFERROR(Q13/R13,"") -> 0 | T13: =SUMIF('ESTATÍSTICAS ATLETAS'!$I:$I,$B13,'ESTATÍSTICAS ATLETAS'!Z:Z) -> 1 | U13: =SUMIF('ESTATÍSTICAS ATLETAS'!$I:$I,$B13,'ESTATÍSTICAS ATLETAS'!AA:AA) -> 3 | V13: =SUMIF('ESTATÍSTICAS ATLETAS'!$I:$I,$B13,'ESTATÍSTICAS ATLETAS'!AB:AB) -> 4 | W13: =V13/E13 -> 2 | X13: =SUMIF('ESTATÍSTICAS ATLETAS'!$I:$I,$B13,'ESTATÍSTICAS ATLETAS'!AC:AC) -> 2 | Y13: =X13/E13 -> 1 | Z13: =SUMIF('ESTATÍSTICAS ATLETAS'!$I:$I,$B13,'ESTATÍSTICAS ATLETAS'!AD:AD) -> 8 | AA13: =SUMIF('ESTATÍSTICAS ATLETAS'!$I:$I,$B13,'ESTATÍSTICAS ATLETAS'!AE:AE) -> 2 | AB13: =SUMIF('ESTATÍSTICAS ATLETAS'!$I:$I,$B13,'ESTATÍSTICAS ATLETAS'!AF:AF) -> 0 | AC13: =SUMIF('ESTATÍSTICAS ATLETAS'!$I:$I,$B13,'ESTATÍSTICAS ATLETAS'!AG:AG) -> 3 | AD13: =SUMIF('ESTATÍSTICAS ATLETAS'!$I:$I,$B13,'ESTATÍSTICAS ATLETAS'!AH:AH) -> 2 | AE13: =SUMIF('ESTATÍSTICAS ATLETAS'!$I:$I,$B13,'ESTATÍSTICAS ATLETAS'!AI:AI) -> 2 | AF13: =SUMIF('ESTATÍSTICAS ATLETAS'!$I:$I,$B13,'ESTATÍSTICAS ATLETAS'!AJ:AJ) -> -11
... A40: 39 | B40: ANINHA | D40: MED UNAERP | E40: =COUNTIF('ESTATÍSTICAS ATLETAS'!I:I,B40) -> 2 | F40: =SUMIF('ESTATÍSTICAS ATLETAS'!I:I,B40,'ESTATÍSTICAS ATLETAS'!M:M) -> 2 | G40: =F40/E40 -> 1 | H40: =SUMIF('ESTATÍSTICAS ATLETAS'!$I:$I,$B40,'ESTATÍSTICAS ATLETAS'!N:N) -> 1 | I40: =SUMIF('ESTATÍSTICAS ATLETAS'!$I:$I,$B40,'ESTATÍSTICAS ATLETAS'!O:O) -> 6 | J40: =IFERROR(H40/I40,"") -> 0.16666667 | K40: =SUMIF('ESTATÍSTICAS ATLETAS'!$I:$I,$B40,'ESTATÍSTICAS ATLETAS'!Q:Q) -> 1 | L40: =SUMIF('ESTATÍSTICAS ATLETAS'!$I:$I,$B40,'ESTATÍSTICAS ATLETAS'!R:R) -> 5 | M40: =IFERROR(K40/L40,"") -> 0.2 | N40: =SUMIF('ESTATÍSTICAS ATLETAS'!$I:$I,$B40,'ESTATÍSTICAS ATLETAS'!T:T) -> 0 | O40: =SUMIF('ESTATÍSTICAS ATLETAS'!$I:$I,$B40,'ESTATÍSTICAS ATLETAS'!U:U) -> 1 | P40: =IFERROR(N40/O40,"") -> 0 | Q40: =SUMIF('ESTATÍSTICAS ATLETAS'!$I:$I,$B40,'ESTATÍSTICAS ATLETAS'!W:W) -> 0 | R40: =SUMIF('ESTATÍSTICAS ATLETAS'!$I:$I,$B40,'ESTATÍSTICAS ATLETAS'!X:X) -> 2 | S40: =IFERROR(Q40/R40,"") -> 0 | T40: =SUMIF('ESTATÍSTICAS ATLETAS'!$I:$I,$B40,'ESTATÍSTICAS ATLETAS'!Z:Z) -> 0 | U40: =SUMIF('ESTATÍSTICAS ATLETAS'!$I:$I,$B40,'ESTATÍSTICAS ATLETAS'!AA:AA) -> 5 | V40: =SUMIF('ESTATÍSTICAS ATLETAS'!$I:$I,$B40,'ESTATÍSTICAS ATLETAS'!AB:AB) -> 5 | W40: =V40/E40 -> 2.5 | X40: =SUMIF('ESTATÍSTICAS ATLETAS'!$I:$I,$B40,'ESTATÍSTICAS ATLETAS'!AC:AC) -> 2 | Y40: =X40/E40 -> 1 | Z40: =SUMIF('ESTATÍSTICAS ATLETAS'!$I:$I,$B40,'ESTATÍSTICAS ATLETAS'!AD:AD) -> 3 | AA40: =SUMIF('ESTATÍSTICAS ATLETAS'!$I:$I,$B40,'ESTATÍSTICAS ATLETAS'!AE:AE) -> 0 | AB40: =SUMIF('ESTATÍSTICAS ATLETAS'!$I:$I,$B40,'ESTATÍSTICAS ATLETAS'!AF:AF) -> 0 | AC40: =SUMIF('ESTATÍSTICAS ATLETAS'!$I:$I,$B40,'ESTATÍSTICAS ATLETAS'!AG:AG) -> 0 | AD40: =SUMIF('ESTATÍSTICAS ATLETAS'!$I:$I,$B40,'ESTATÍSTICAS ATLETAS'!AH:AH) -> 1 | AE40: =SUMIF('ESTATÍSTICAS ATLETAS'!$I:$I,$B40,'ESTATÍSTICAS ATLETAS'!AI:AI) -> -5 | AF40: =SUMIF('ESTATÍSTICAS ATLETAS'!$I:$I,$B40,'ESTATÍSTICAS ATLETAS'!AJ:AJ) -> -1

Sheet ESTATÍSTICAS ATLETAS
A1: CÉLULA | B1: JOGO | C1: FASE | D1: DATA | E1: MÊS | F1: ANO | G1: EQUIPE | H1: ADVERSÁRIO | I1: APELIDO | J1: STATUS | K1: ANO | L1: NÚMERO | M1: PONTOS | N1: FGM | O1: FGA | P1: %FG | Q1: 2PM | R1: 2PA | S1: %2P | T1: 3PM | U1: 3PA | V1: %3P | W1: FTM | X1: FTA | Y1: %FT | Z1: REB O | AA1: REB D | AB1: TOTAL REB | AC1: AST | AD1: ERROS | AE1: ROUB | AF1: TOCOS | AG1: FALTAS C | AH1: FALTAS S | AI1: PLUS/MINUS | AJ1: EFICIÊNCIA
A2: 35 | B2: 2 | C2: REGULAR | D2: 45916 | E2: SETEMBRO | F2: 2025 | G2: MED UNAERP | H2: FILÔ USP RP | I2: MAFÊ | J2: TITULAR | K2: =VLOOKUP(I2,'LISTA DE ATLETAS'!D:E,2,FALSE) | L2: 18 | M2: =(ATLETAS[2PM]*2)+(ATLETAS[3PM]*3)+(ATLETAS[FTM]) -> 14 | N2: =ATLETAS[2PM]+ATLETAS[3PM] -> 7 | O2: =ATLETAS[2PA]+ATLETAS[3PA] -> 14 | P2: =IFERROR(ATLETAS[FGM]/ATLETAS[FGA],"") -> 0.5 | Q2: 7 | R2: 14 | S2: =IFERROR(ATLETAS[2PM]/ATLETAS[2PA],"") -> 0.5 | T2: 0 | U2: 0 | V2: =IFERROR(ATLETAS[3PM]/ATLETAS[3PA],"") | W2: 0 | X2: 0 | Y2: =IFERROR(ATLETAS[FTM]/ATLETAS[FTA],"") | Z2: 2 | AA2: 10 | AB2: =ATLETAS[REB O]+ATLETAS[REB D] -> 12 | AC2: 3 | AD2: 6 | AE2: 10 | AF2: 5 | AG2: 3 | AH2: 1 | AI2: 15 | AJ2: =ATLETAS[PONTOS]+ATLETAS[TOTAL REB]+ATLETAS[AST]+ATLETAS[TOCOS]+ATLETAS[ROUB]-(ATLETAS[FGA]-ATLETAS[FGM])-(ATLETAS[FTA]-ATLETAS[FTM])-ATLETAS[ERROS] -> 31
A3: 59 | B3: 3 | C3: REGULAR | D3: 45929 | E3: SETEMBRO | F3: 2025 | G3: LUS USP RP | H3: MED UNAERP | I3: BABY | J3: TITULAR | K3: =VLOOKUP(I3,'LISTA DE ATLETAS'!D:E,2,FALSE) | L3: 31 | M3: =(ATLETAS[2PM]*2)+(ATLETAS[3PM]*3)+(ATLETAS[FTM]) -> 13 | N3: =ATLETAS[2PM]+ATLETAS[3PM] -> 6 | O3: =ATLETAS[2PA]+ATLETAS[3PA] -> 31 | P3: =IFERROR(ATLETAS[FGM]/ATLETAS[FGA],"") -> 0.19354839 | Q3: 5 | R3: 23 | S3: =IFERROR(ATLETAS[2PM]/ATLETAS[2PA],"") -> 0.2173913 | T3: 1 | U3: 8 | V3: =IFERROR(ATLETAS[3PM]/ATLETAS[3PA],"") -> 0.125 | W3: 0 | X3: 2 | Y3: =IFERROR(ATLETAS[FTM]/ATLETAS[FTA],"") -> 0 | Z3: 6 | AA3: 6 | AB3: =ATLETAS[REB O]+ATLETAS[REB D] -> 12 | AC3: 2 | AD3: 6 | AE3: 10 | AF3: 1 | AG3: 5 | AH3: 1 | AI3: -3 | AJ3: =ATLETAS[PONTOS]+ATLETAS[TOTAL REB]+ATLETAS[AST]+ATLETAS[TOCOS]+ATLETAS[ROUB]-(ATLETAS[FGA]-ATLETAS[FGM])-(ATLETAS[FTA]-ATLETAS[FTM])-ATLETAS[ERROS] -> 5
A4: 101 | B4: 6 | C4: REGULAR | D4: 45971 | E4: NOVEMBRO | F4: 2025 | G4: LUS USP RP | H4: MED UNAERP | I4: BABY | J4: TITULAR | K4: =VLOOKUP(I4,'LISTA DE ATLETAS'!D:E,2,FALSE) | L4: 31 | M4: =(ATLETAS[2PM]*2)+(ATLETAS[3PM]*3)+(ATLETAS[FTM]) -> 13 | N4: =ATLETAS[2PM]+ATLETAS[3PM] -> 5 | O4: =ATLETAS[2PA]+ATLETAS[3PA] -> 22 | P4: =IFERROR(ATLETAS[FGM]/ATLETAS[FGA],"") -> 0.22727273 | Q4: 4 | R4: 18 | S4: =IFERROR(ATLETAS[2PM]/ATLETAS[2PA],"") -> 0.22222222 | T4: 1 | U4: 4 | V4: =IFERROR(ATLETAS[3PM]/ATLETAS[3PA],"") -> 0.25 | W4: 2 | X4: 6 | Y4: =IFERROR(ATLETAS[FTM]/ATLETAS[FTA],"") -> 0.33333333 | Z4: 7 | AA4: 4 | AB4: =ATLETAS[REB O]+ATLETAS[REB D] -> 11 | AC4: 3 | AD4: 5 | AE4: 7 | AF4: 1 | AG4: 4 | AH4: 8 | AI4: 11 | AJ4: =ATLETAS[PONTOS]+ATLETAS[TOTAL REB]+ATLETAS[AST]+ATLETAS[TOCOS]+ATLETAS[ROUB]-(ATLETAS[FGA]-ATLETAS[FGM])-(ATLETAS[FTA]-ATLETAS[FTM])-ATLETAS[ERROS] -> 9
A5: 45 | B5: 3 | C5: REGULAR | D5: 45929 | E5: SETEMBRO | F5: 2025 | G5: MED UNAERP | H5: LUS USP RP | I5: MAFÊ | J5: TITULAR | K5: =VLOOKUP(I5,'LISTA DE ATLETAS'!D:E,2,FALSE) | L5: 18 | M5: =(ATLETAS[2PM]*2)+(ATLETAS[3PM]*3)+(ATLETAS[FTM]) -> 11 | N5: =ATLETAS[2PM]+ATLETAS[3PM] -> 4 | O5: =ATLETAS[2PA]+ATLETAS[3PA] -> 10 | P5: =IFERROR(ATLETAS[FGM]/ATLETAS[FGA],"") -> 0.4 | Q5: 4 | R5: 7 | S5: =IFERROR(ATLETAS[2PM]/ATLETAS[2PA],"") -> 0.57142857 | T5: 0 | U5: 3 | V5: =IFERROR(ATLETAS[3PM]/ATLETAS[3PA],"") -> 0 | W5: 3 | X5: 6 | Y5: =IFERROR(ATLETAS[FTM]/ATLETAS[FTA],"") -> 0.5 | Z5: 0 | AA5: 10 | AB5: =ATLETAS[REB O]+ATLETAS[REB D] -> 10 | AC5: 4 | AD5: 8 | AE5: 3 | AF5: 7 | AG5: 0 | AH5: 3 | AI5: 3 | AJ5: =ATLETAS[PONTOS]+ATLETAS[TOTAL REB]+ATLETAS[AST]+ATLETAS[TOCOS]+ATLETAS[ROUB]-(ATLETAS[FGA]-ATLETAS[FGM])-(ATLETAS[FTA]-ATLETAS[FTM])-ATLETAS[ERROS] -> 18
A6: 39 | B6: 2 | C6: REGULAR | D6: 45916 | E6: SETEMBRO | F6: 2025 | G6: MED UNAERP | H6: FILÔ USP RP | I6: BIA | J6: TITULAR | K6: =VLOOKUP(I6,'LISTA DE ATLETAS'!D:E,2,FALSE) | L6: 32 | M6: =(ATLETAS[2PM]*2)+(ATLETAS[3PM]*3)+(ATLETAS[FTM]) -> 10 | N6: =ATLETAS[2PM]+ATLETAS[3PM] -> 5 | O6: =ATLETAS[2PA]+ATLETAS[3PA] -> 16 | P6: =IFERROR(ATLETAS[FGM]/ATLETAS[FGA],"") -> 0.3125 | Q6: 5 | R6: 16 | S6: =IFERROR(ATLETAS[2PM]/ATLETAS[2PA],"") -> 0.3125 | T6: 0 | U6: 0 | V6: =IFERROR(ATLETAS[3PM]/ATLETAS[3PA],"") | W6: 0 | X6: 5 | Y6: =IFERROR(ATLETAS[FTM]/ATLETAS[FTA],"") -> 0 | Z6: 6 | AA6: 9 | AB6: =ATLETAS[REB O]+ATLETAS[REB D] -> 15 | AC6: 1 | AD6: 8 | AE6: 2 | AF6: 0 | AG6: 1 | AH6: 9 | AI6: 7 | AJ6: =ATLETAS[PONTOS]+ATLETAS[TOTAL REB]+ATLETAS[AST]+ATLETAS[TOCOS]+ATLETAS[ROUB]-(ATLETAS[FGA]-ATLETAS[FGM])-(ATLETAS[FTA]-ATLETAS[FTM])-ATLETAS[ERROS] -> 4
A7: 78 | B7: 4 | C7: REGULAR | D7: 45950 | E7: OUTUBRO | F7: 2025 | G7: FILÔ USP RP | H7: MED UNAERP | I7: WINNIE | J7: RESERVA | K7: =VLOOKUP(I7,'LISTA DE ATLETAS'!D:E,2,FALSE) | L7: 24 | M7: =(ATLETAS[2PM]*2)+(ATLETAS[3PM]*3)+(ATLETAS[FTM]) -> 10 | N7: =ATLETAS[2PM]+ATLETAS[3PM] -> 4 | O7: =ATLETAS[2PA]+ATLETAS[3PA] -> 21 | P7: =IFERROR(ATLETAS[FGM]/ATLETAS[FGA],"") -> 0.19047619 | Q7: 2 | R7: 15 | S7: =IFERROR(ATLETAS[2PM]/ATLETAS[2PA],"") -> 0.13333333 | T7: 2 | U7: 6 | V7: =IFERROR(ATLETAS[3PM]/ATLETAS[3PA],"") -> 0.33333333 | W7: 0 | X7: 0 | Y7: =IFERROR(ATLETAS[FTM]/ATLETAS[FTA],"") | Z7: 2 | AA7: 2 | AB7: =ATLETAS[REB O]+ATLETAS[REB D] -> 4 | AC7: 2 | AD7: 3 | AE7: 3 | AF7: 0 | AG7: 1 | AH7: 0 | AI7: 3 | AJ7: =ATLETAS[PONTOS]+ATLETAS[TOTAL REB]+ATLETAS[AST]+ATLETAS[TOCOS]+ATLETAS[ROUB]-(ATLETAS[FGA]-ATLETAS[FGM])-(ATLETAS[FTA]-ATLETAS[FTM])-ATLETAS[ERROS] -> -1
A8: 67 | B8: 4 | C8: REGULAR | D8: 45950 | E8: OUTUBRO | F8: 2025 | G8: MED UNAERP | H8: FILÔ USP RP | I8: MAFÊ | J8: TITULAR | K8: =VLOOKUP(I8,'LISTA DE ATLETAS'!D:E,2,FALSE) | L8: 18 | M8: =(ATLETAS[2PM]*2)+(ATLETAS[3PM]*3)+(ATLETAS[FTM]) -> 8 | N8: =ATLETAS[2PM]+ATLETAS[3PM] -> 3 | O8: =ATLETAS[2PA]+ATLETAS[3PA] -> 11 | P8: =IFERROR(ATLETAS[FGM]/ATLETAS[FGA],"") -> 0.27272727 | Q8: 3 | R8: 11 | S8: =IFERROR(ATLETAS[2PM]/ATLETAS[2PA],"") -> 0.27272727 | T8: 0 | U8: 0 | V8: =IFERROR(ATLETAS[3PM]/ATLETAS[3PA],"") | W8: 2 | X8: 6 | Y8: =IFERROR(ATLETAS[FTM]/ATLETAS[FTA],"") -> 0.33333333 | Z8: 2 | AA8: 4 | AB8: =ATLETAS[REB O]+ATLETAS[REB D] -> 6 | AC8: 4 | AD8: 7 | AE8: 4 | AF8: 6 | AG8: 2 | AH8: 3 | AI8: -1 | AJ8: =ATLETAS[PONTOS]+ATLETAS[TOTAL REB]+ATLETAS[AST]+ATLETAS[TOCOS]+ATLETAS[ROUB]-(ATLETAS[FGA]-ATLETAS[FGM])-(ATLETAS[FTA]-ATLETAS[FTM])-ATLETAS[ERROS] -> 9
A9: 98 | B9: 6 | C9: REGULAR | D9: 45971 | E9: NOVEMBRO | F9: 2025 | G9: LUS USP RP | H9: MED UNAERP | I9: BT | J9: RESERVA | K9: =VLOOKUP(I9,'LISTA DE ATLETAS'!D:E,2,FALSE) | L9: 13 | M9: =(ATLETAS[2PM]*2)+(ATLETAS[3PM]*3)+(ATLETAS[FTM]) -> 8 | N9: =ATLETAS[2PM]+ATLETAS[3PM] -> 4 | O9: =ATLETAS[2PA]+ATLETAS[3PA] -> 11 | P9: =IFERROR(ATLETAS[FGM]/ATLETAS[FGA],"") -> 0.36363636 | Q9: 4 | R9: 11 | S9: =IFERROR(ATLETAS[2PM]/ATLETAS[2PA],"") -> 0.36363636 | T9: 0 | U9: 0 | V9: =IFERROR(ATLETAS[3PM]/ATLETAS[3PA],"") | W9: 0 | X9: 4 | Y9: =IFERROR(ATLETAS[FTM]/ATLETAS[FTA],"") -> 0 | Z9: 6 | AA9: 3 | AB9: =ATLETAS[REB O]+ATLETAS[REB D] -> 9 | AC9: 0 | AD9: 2 | AE9: 0 | AF9: 0 | AG9: 0 | AH9: 2 | AI9: 8 | AJ9: =ATLETAS[PONTOS]+ATLETAS[TOTAL REB]+ATLETAS[AST]+ATLETAS[TOCOS]+ATLETAS[ROUB]-(ATLETAS[FGA]-ATLETAS[FGM])-(ATLETAS[FTA]-ATLETAS[FTM])-ATLETAS[ERROS] -> 4
A10: 93 | B10: 5 | C10: REGULAR | D10: 45964 | E10: NOVEMBRO | F10: 2025 | G10: FILÔ USP RP | H10: LUS USP RP | I10: QUIRO | J10: RESERVA | K10: =VLOOKUP(I10,'LISTA DE ATLETAS'!D:E,2,FALSE) | L10: 14 | M10: =(ATLETAS[2PM]*2)+(ATLETAS[3PM]*3)+(ATLETAS[FTM]) -> 7 | N10: =ATLETAS[2PM]+ATLETAS[3PM] -> 2 | O10: =ATLETAS[2PA]+ATLETAS[3PA] -> 9 | P10: =IFERROR(ATLETAS[FGM]/ATLETAS[FGA],"") -> 0.22222222 | Q10: 2 | R10: 8 | S10: =IFERROR(ATLETAS[2PM]/ATLETAS[2PA],"") -> 0.25 | T10: 0 | U10: 1 | V10: =IFERROR(ATLETAS[3PM]/ATLETAS[3PA],"") -> 0 | W10: 3 | X10: 4 | Y10: =IFERROR(ATLETAS[FTM]/ATLETAS[FTA],"") -> 0.75 | Z10: 1 | AA10: 3 | AB10: =ATLETAS[REB O]+ATLETAS[REB D] -> 4 | AC10: 1 | AD10: 3 | AE10: 1 | AF10: 0 | AG10: 0 | AH10: 2 | AI10: 3 | AJ10: =ATLETAS[PONTOS]+ATLETAS[TOTAL REB]+ATLETAS[AST]+ATLETAS[TOCOS]+ATLETAS[ROUB]-(ATLETAS[FGA]-ATLETAS[FGM])-(ATLETAS[FTA]-ATLETAS[FTM])-ATLETAS[ERROS] -> 2
A11: 8 | B11: 1 | C11: REGULAR | D11: 45896 | E11: AGOSTO | F11: 2025 | G11: LUS USP RP | H11: FILÔ USP RP | I11: SUFOCO | J11: RESERVA | K11: =VLOOKUP(I11,'LISTA DE ATLETAS'!D:E,2,FALSE) | L11: 94 | M11: =(ATLETAS[2PM]*2)+(ATLETAS[3PM]*3)+(ATLETAS[FTM]) -> 6 | N11: =ATLETAS[2PM]+ATLETAS[3PM] -> 2 | O11: =ATLETAS[2PA]+ATLETAS[3PA] -> 17 | P11: =IFERROR(ATLETAS[FGM]/ATLETAS[FGA],"") -> 0.11764706 | Q11: 1 | R11: 11 | S11: =IFERROR(ATLETAS[2PM]/ATLETAS[2PA],"") -> 0.090909091 | T11: 1 | U11: 6 | V11: =IFERROR(ATLETAS[3PM]/ATLETAS[3PA],"") -> 0.16666667 | W11: 1 | X11: 5 | Y11: =IFERROR(ATLETAS[FTM]/ATLETAS[FTA],"") -> 0.2 | Z11: 4 | AA11: 6 | AB11: =ATLETAS[REB O]+ATLETAS[REB D] -> 10 | AC11: 2 | AD11: 6 | AE11: 12 | AF11: 0 | AG11: 0 | AH11: 3 | AI11: -4 | AJ11: =ATLETAS[PONTOS]+ATLETAS[TOTAL REB]+ATLETAS[AST]+ATLETAS[TOCOS]+ATLETAS[ROUB]-(ATLETAS[FGA]-ATLETAS[FGM])-(ATLETAS[FTA]-ATLETAS[FTM])-ATLETAS[ERROS] -> 5
A12: 14 | B12: 1 | C12: REGULAR | D12: 45896 | E12: AGOSTO | F12: 2025 | G12: FILÔ USP RP | H12: LUS USP RP | I12: AMINA | J12: TITULAR | K12: =VLOOKUP(I12,'LISTA DE ATLETAS'!D:E,2,FALSE) | L12: 23 | M12: =(ATLETAS[2PM]*2)+(ATLETAS[3PM]*3)+(ATLETAS[FTM]) -> 6 | N12: =ATLETAS[2PM]+ATLETAS[3PM] -> 2 | O12: =ATLETAS[2PA]+ATLETAS[3PA] -> 4 | P12: =IFERROR(ATLETAS[FGM]/ATLETAS[FGA],"") -> 0.5 | Q12: 2 | R12: 4 | S12: =IFERROR(ATLETAS[2PM]/ATLETAS[2PA],"") -> 0.5 | T12: 0 | U12: 0 | V12: =IFERROR(ATLETAS[3PM]/ATLETAS[3PA],"") | W12: 2 | X12: 4 | Y12: =IFERROR(ATLETAS[FTM]/ATLETAS[FTA],"") -> 0.5 | Z12: 1 | AA12: 5 | AB12: =ATLETAS[REB O]+ATLETAS[REB D] -> 6 | AC12: 1 | AD12: 4 | AE12: 1 | AF12: 0 | AG12: 0 | AH12: 2 | AI12: 1 | AJ12: =ATLETAS[PONTOS]+ATLETAS[TOTAL REB]+ATLETAS[AST]+ATLETAS[TOCOS]+ATLETAS[ROUB]-(ATLETAS[FGA]-ATLETAS[FGM])-(ATLETAS[FTA]-ATLETAS[FTM])-ATLETAS[ERROS] -> 6
A13: 38 | B13: 2 | C13: REGULAR | D13: 45916 | E13: SETEMBRO | F13: 2025 | G13: MED UNAERP | H13: FILÔ USP RP | I13: ISA | J13: TITULAR | K13: =VLOOKUP(I13,'LISTA DE ATLETAS'!D:E,2,FALSE) | L13: 31 | M13: =(ATLETAS[2PM]*2)+(ATLETAS[3PM]*3)+(ATLETAS[FTM]) -> 6 | N13: =ATLETAS[2PM]+ATLETAS[3PM] -> 3 | O13: =ATLETAS[2PA]+ATLETAS[3PA] -> 12 | P13: =IFERROR(ATLETAS[FGM]/ATLETAS[FGA],"") -> 0.25 | Q13: 3 | R13: 12 | S13: =IFERROR(ATLETAS[2PM]/ATLETAS[2PA],"") -> 0.25 | T13: 0 | U13: 0 | V13: =IFERROR(ATLETAS[3PM]/ATLETAS[3PA],"") | W13: 0 | X13: 0 | Y13: =IFERROR(ATLETAS[FTM]/ATLETAS[FTA],"") | Z13: 2 | AA13: 0 | AB13: =ATLETAS[REB O]+ATLETAS[REB D] -> 2 | AC13: 1 | AD13: 4 | AE13: 1 | AF13: 0 | AG13: 2 | AH13: 0 | AI13: 5 | AJ13: =ATLETAS[PONTOS]+ATLETAS[TOTAL REB]+ATLETAS[AST]+ATLETAS[TOCOS]+ATLETAS[ROUB]-(ATLETAS[FGA]-ATLETAS[FGM])-(ATLETAS[FTA]-ATLETAS[FTM])-ATLETAS[ERROS] -> -3
... A91: 56 | B91: 3 | C91: REGULAR | D91: 45929 | E91: SETEMBRO | F91: 2025 | G91: LUS USP RP | H91: MED UNAERP | I91: ELÉTRICA | J91: TITULAR | K91: =VLOOKUP(I91,'LISTA DE ATLETAS'!D:E,2,FALSE) | L91: 16 | M91: =(ATLETAS[2PM]*2)+(ATLETAS[3PM]*3)+(ATLETAS[FTM]) -> 0 | N91: =ATLETAS[2PM]+ATLETAS[3PM] -> 0 | O91: =ATLETAS[2PA]+ATLETAS[3PA] -> 2 | P91: =IFERROR(ATLETAS[FGM]/ATLETAS[FGA],"") -> 0 | Q91: 0 | R91: 1 | S91: =IFERROR(ATLETAS[2PM]/ATLETAS[2PA],"") -> 0 | T91: 0 | U91: 1 | V91: =IFERROR(ATLETAS[3PM]/ATLETAS[3PA],"") -> 0 | W91: 0 | X91: 0 | Y91: =IFERROR(ATLETAS[FTM]/ATLETAS[FTA],"") | Z91: 0 | AA91: 0 | AB91: =ATLETAS[REB O]+ATLETAS[REB D] -> 0 | AC91: 0 | AD91: 1 | AE91: 0 | AF91: 0 | AG91: 1 | AH91: 0 | AI91: 11 | AJ91: =ATLETAS[PONTOS]+ATLETAS[TOTAL REB]+ATLETAS[AST]+ATLETAS[TOCOS]+ATLETAS[ROUB]-(ATLETAS[FGA]-ATLETAS[FGM])-(ATLETAS[FTA]-ATLETAS[FTM])-ATLETAS[ERROS] -> -3
A92: 57 | B92: 3 | C92: REGULAR | D92: 45929 | E92: SETEMBRO | F92: 2025 | G92: LUS USP RP | H92: MED UNAERP | I92: MABS | J92: RESERVA | K92: =VLOOKUP(I92,'LISTA DE ATLETAS'!D:E,2,FALSE) | L92: 24 | M92: =(ATLETAS[2PM]*2)+(ATLETAS[3PM]*3)+(ATLETAS[FTM]) -> 0 | N92: =ATLETAS[2PM]+ATLETAS[3PM] -> 0 | O92: =ATLETAS[2PA]+ATLETAS[3PA] -> 0 | P92: =IFERROR(ATLETAS[FGM]/ATLETAS[FGA],"") | S92: =IFERROR(ATLETAS[2PM]/ATLETAS[2PA],"") | T92: 0 | U92: 0 | V92: =IFERROR(ATLETAS[3PM]/ATLETAS[3PA],"") | W92: 0 | X92: 0 | Y92: =IFERROR(ATLETAS[FTM]/ATLETAS[FTA],"") | Z92: 0 | AA92: 0 | AB92: =ATLETAS[REB O]+ATLETAS[REB D] -> 0 | AC92: 0 | AD92: 0 | AF92: 0 | AG92: 0 | AH92: 0 | AI92: 0 | AJ92: 0
A93: 61 | B93: 3 | C93: REGULAR | D93: 45929 | E93: SETEMBRO | F93: 2025 | G93: LUS USP RP | H93: MED UNAERP | I93: MARIÊ | J93: RESERVA | K93: =VLOOKUP(I93,'LISTA DE ATLETAS'!D:E,2,FALSE) | L93: 94 | M93: =(ATLETAS[2PM]*2)+(ATLETAS[3PM]*3)+(ATLETAS[FTM]) -> 0 | N93: =ATLETAS[2PM]+ATLETAS[3PM] -> 0 | O93: =ATLETAS[2PA]+ATLETAS[3PA] -> 0 | P93: =IFERROR(ATLETAS[FGM]/ATLETAS[FGA],"") | Q93: 0 | R93: 0 | S93: =IFERROR(ATLETAS[2PM]/ATLETAS[2PA],"") | T93: 0 | U93: 0 | V93: =IFERROR(ATLETAS[3PM]/ATLETAS[3PA],"") | W93: 0 | X93: 0 | Y93: =IFERROR(ATLETAS[FTM]/ATLETAS[FTA],"") | Z93: 0 | AA93: 0 | AB93: =ATLETAS[REB O]+ATLETAS[REB D] -> 0 | AC93: 0 | AD93: 2 | AE93: 0 | AF93: 0 | AG93: 0 | AH93: 0 | AI93: -9 | AJ93: =ATLETAS[PONTOS]+ATLETAS[TOTAL REB]+ATLETAS[AST]+ATLETAS[TOCOS]+ATLETAS[ROUB]-(ATLETAS[FGA]-ATLETAS[FGM])-(ATLETAS[FTA]-ATLETAS[FTM])-ATLETAS[ERROS] -> -2
A94: 62 | B94: 3 | C94: REGULAR | D94: 45929 | E94: SETEMBRO | F94: 2025 | G94: LUS USP RP | H94: MED UNAERP | I94: BANHO | J94: RESERVA | K94: =VLOOKUP(I94,'LISTA DE ATLETAS'!D:E,2,FALSE) | L94: 98 | M94: =(ATLETAS[2PM]*2)+(ATLETAS[3PM]*3)+(ATLETAS[FTM]) -> 0 | N94: =ATLETAS[2PM]+ATLETAS[3PM] -> 0 | O94: =ATLETAS[2PA]+ATLETAS[3PA] -> 0 | P94: =IFERROR(ATLETAS[FGM]/ATLETAS[FGA],"") | Q94: 0 | R94: 0 | S94: =IFERROR(ATLETAS[2PM]/ATLETAS[2PA],"") | T94: 0 | U94: 0 | V94: =IFERROR(ATLETAS[3PM]/ATLETAS[3PA],"") | W94: 0 | X94: 0 | Y94: =IFERROR(ATLETAS[FTM]/ATLETAS[FTA],"") | Z94: 0 | AA94: 0 | AB94: =ATLETAS[REB O]+ATLETAS[REB D] -> 0 | AC94: 0 | AD94: 0 | AE94: 0 | AF94: 0 | AG94: 0 | AH94: 0 | AI94: -2 | AJ94: =ATLETAS[PONTOS]+ATLETAS[TOTAL REB]+ATLETAS[AST]+ATLETAS[TOCOS]+ATLETAS[ROUB]-(ATLETAS[FGA]-ATLETAS[FGM])-(ATLETAS[FTA]-ATLETAS[FTM])-ATLETAS[ERROS] -> 0
A95: 64 | B95: 4 | C95: REGULAR | D95: 45950 | E95: OUTUBRO | F95: 2025 | G95: MED UNAERP | H95: FILÔ USP RP | I95: TEREZA | J95: RESERVA | K95: =VLOOKUP(I95,'LISTA DE ATLETAS'!D:E,2,FALSE) | L95: 6 | M95: =(ATLETAS[2PM]*2)+(ATLETAS[3PM]*3)+(ATLETAS[FTM]) -> 0 | N95: =ATLETAS[2PM]+ATLETAS[3PM] -> 0 | O95: =ATLETAS[2PA]+ATLETAS[3PA] -> 2 | P95: =IFERROR(ATLETAS[FGM]/ATLETAS[FGA],"") -> 0 | Q95: 0 | R95: 2 | S95: =IFERROR(ATLETAS[2PM]/ATLETAS[2PA],"") -> 0 | T95: 0 | U95: 0 | V95: =IFERROR(ATLETAS[3PM]/ATLETAS[3PA],"") | W95: 0 | X95: 0 | Y95: =IFERROR(ATLETAS[FTM]/ATLETAS[FTA],"") | Z95: 2 | AA95: 1 | AB95: =ATLETAS[REB O]+ATLETAS[REB D] -> 3 | AC95: 0 | AD95: 0 | AE95: 0 | AF95: 0 | AG95: 0 | AH95: 0 | AI95: -6 | AJ95: =ATLETAS[PONTOS]+ATLETAS[TOTAL REB]+ATLETAS[AST]+ATLETAS[TOCOS]+ATLETAS[ROUB]-(ATLETAS[FGA]-ATLETAS[FGM])-(ATLETAS[FTA]-ATLETAS[FTM])-ATLETAS[ERROS] -> 1
A96: 66 | B96: 4 | C96: REGULAR | D96: 45950 | E96: OUTUBRO | F96: 2025 | G96: MED UNAERP | H96: FILÔ USP RP | I96: BRUNNA | J96: RESERVA | K96: =VLOOKUP(I96,'LISTA DE ATLETAS'!D:E,2,FALSE) | L96: 14 | M96: =(ATLETAS[2PM]*2)+(ATLETAS[3PM]*3)+(ATLETAS[FTM]) -> 0 | N96: =ATLETAS[2PM]+ATLETAS[3PM] -> 0 | O96: =ATLETAS[2PA]+ATLETAS[3PA] -> 0 | P96: =IFERROR(ATLETAS[FGM]/ATLETAS[FGA],"") | S96: =IFERROR(ATLETAS[2PM]/ATLETAS[2PA],"") | V96: =IFERROR(ATLETAS[3PM]/ATLETAS[3PA],"") | Y96: =IFERROR(ATLETAS[FTM]/ATLETAS[FTA],"") | AB96: =ATLETAS[REB O]+ATLETAS[REB D] -> 0 | AJ96: =ATLETAS[PONTOS]+ATLETAS[TOTAL REB]+ATLETAS[AST]+ATLETAS[TOCOS]+ATLETAS[ROUB]-(ATLETAS[FGA]-ATLETAS[FGM])-(ATLETAS[FTA]-ATLETAS[FTM])-ATLETAS[ERROS] -> 0
A97: 73 | B97: 4 | C97: REGULAR | D97: 45950 | E97: OUTUBRO | F97: 2025 | G97: FILÔ USP RP | H97: MED UNAERP | I97: JADE | J97: TITULAR | K97: =VLOOKUP(I97,'LISTA DE ATLETAS'!D:E,2,FALSE) | L97: 7 | M97: =(ATLETAS[2PM]*2)+(ATLETAS[3PM]*3)+(ATLETAS[FTM]) -> 0 | N97: =ATLETAS[2PM]+ATLETAS[3PM] -> 0 | O97: =ATLETAS[2PA]+ATLETAS[3PA] -> 2 | P97: =IFERROR(ATLETAS[FGM]/ATLETAS[FGA],"") -> 0 | Q97: 0 | R97: 2 | S97: =IFERROR(ATLETAS[2PM]/ATLETAS[2PA],"") -> 0 | T97: 0 | U97: 0 | V97: =IFERROR(ATLETAS[3PM]/ATLETAS[3PA],"") | W97: 0 | X97: 0 | Y97: =IFERROR(ATLETAS[FTM]/ATLETAS[FTA],"") | Z97: 3 | AA97: 2 | AB97: =ATLETAS[REB O]+ATLETAS[REB D] -> 5 | AC97: 0 | AD97: 2 | AE97: 3 | AF97: 1 | AG97: 0 | AH97: 0 | AI97: 1 | AJ97: =ATLETAS[PONTOS]+ATLETAS[TOTAL REB]+ATLETAS[AST]+ATLETAS[TOCOS]+ATLETAS[ROUB]-(ATLETAS[FGA]-ATLETAS[FGM])-(ATLETAS[FTA]-ATLETAS[FTM])-ATLETAS[ERROS] -> 5
A98: 75 | B98: 4 | C98: REGULAR | D98: 45950 | E98: OUTUBRO | F98: 2025 | G98: FILÔ USP RP | H98: MED UNAERP | I98: ZIMI | J98: TITULAR | K98: =VLOOKUP(I98,'LISTA DE ATLETAS'!D:E,2,FALSE) | L98: 9 | M98: =(ATLETAS[2PM]*2)+(ATLETAS[3PM]*3)+(ATLETAS[FTM]) -> 0 | N98: =ATLETAS[2PM]+ATLETAS[3PM] -> 0 | O98: =ATLETAS[2PA]+ATLETAS[3PA] -> 7 | P98: =IFERROR(ATLETAS[FGM]/ATLETAS[FGA],"") -> 0 | Q98: 0 | R98: 7 | S98: =IFERROR(ATLETAS[2PM]/ATLETAS[2PA],"") -> 0 | T98: 0 | U98: 0 | V98: =IFERROR(ATLETAS[3PM]/ATLETAS[3PA],"") | W98: 0 | X98: 0 | Y98: =IFERROR(ATLETAS[FTM]/ATLETAS[FTA],"") | Z98: 0 | AA98: 1 | AB98: =ATLETAS[REB O]+ATLETAS[REB D] -> 1 | AC98: 0 | AD98: 3 | AE98: 0 | AF98: 0 | AG98: 2 | AH98: 0 | AI98: -13 | AJ98: =ATLETAS[PONTOS]+ATLETAS[TOTAL REB]+ATLETAS[AST]+ATLETAS[TOCOS]+ATLETAS[ROUB]-(ATLETAS[FGA]-ATLETAS[FGM])-(ATLETAS[FTA]-ATLETAS[FTM])-ATLETAS[ERROS] -> -9
A99: 76 | B99: 4 | C99: REGULAR | D99: 45950 | E99: OUTUBRO | F99: 2025 | G99: FILÔ USP RP | H99: MED UNAERP | I99: COLÔ | J99: TITULAR | K99: =VLOOKUP(I99,'LISTA DE ATLETAS'!D:E,2,FALSE) | L99: 11 | M99: =(ATLETAS[2PM]*2)+(ATLETAS[3PM]*3)+(ATLETAS[FTM]) -> 0 | N99: =ATLETAS[2PM]+ATLETAS[3PM] -> 0 | O99: =ATLETAS[2PA]+ATLETAS[3PA] -> 10 | P99: =IFERROR(ATLETAS[FGM]/ATLETAS[FGA],"") -> 0 | Q99: 0 | R99: 8 | S99: =IFERROR(ATLETAS[2PM]/ATLETAS[2PA],"") -> 0 | T99: 0 | U99: 2 | V99: =IFERROR(ATLETAS[3PM]/ATLETAS[3PA],"") -> 0 | W99: 0 | X99: 0 | Y99: =IFERROR(ATLETAS[FTM]/ATLETAS[FTA],"") | Z99: 0 | AA99: 11 | AB99: =ATLETAS[REB O]+ATLETAS[REB D] -> 11 | AC99: 2 | AD99: 3 | AE99: 0 | AF99: 3 | AG99: 0 | AH99: 0 | AI99: 1 | AJ99: =ATLETAS[PONTOS]+ATLETAS[TOTAL REB]+ATLETAS[AST]+ATLETAS[TOCOS]+ATLETAS[ROUB]-(ATLETAS[FGA]-ATLETAS[FGM])-(ATLETAS[FTA]-ATLETAS[FTM])-ATLETAS[ERROS] -> 3
A100: 77 | B100: 4 | C100: REGULAR | D100: 45950 | E100: OUTUBRO | F100: 2025 | G100: FILÔ USP RP | H100: MED UNAERP | I100: QUIRO | J100: TITULAR | K100: =VLOOKUP(I100,'LISTA DE ATLETAS'!D:E,2,FALSE) | L100: 14 | M100: =(ATLETAS[2PM]*2)+(ATLETAS[3PM]*3)+(ATLETAS[FTM]) -> 0 | N100: =ATLETAS[2PM]+ATLETAS[3PM] -> 0 | O100: =ATLETAS[2PA]+ATLETAS[3PA] -> 2 | P100: =IFERROR(ATLETAS[FGM]/ATLETAS[FGA],"") -> 0 | Q100: 0 | R100: 1 | S100: =IFERROR(ATLETAS[2PM]/ATLETAS[2PA],"") -> 0 | T100: 0 | U100: 1 | V100: =IFERROR(ATLETAS[3PM]/ATLETAS[3PA],"") -> 0 | W100: 0 | X100: 0 | Y100: =IFERROR(ATLETAS[FTM]/ATLETAS[FTA],"") | Z100: 0 | AA100: 0 | AB100: =ATLETAS[REB O]+ATLETAS[REB D] -> 0 | AC100: 0 | AD100: 0 | AE100: 1 | AF100: 0 | AG100: 1 | AH100: 0 | AI100: -5 | AJ100: =ATLETAS[PONTOS]+ATLETAS[TOTAL REB]+ATLETAS[AST]+ATLETAS[TOCOS]+ATLETAS[ROUB]-(ATLETAS[FGA]-ATLETAS[FGM])-(ATLETAS[FTA]-ATLETAS[FTM])-ATLETAS[ERROS] -> -1
A101: 79 | B101: 4 | C101: REGULAR | D101: 45950 | E101: OUTUBRO | F101: 2025 | G101: FILÔ USP RP | H101: MED UNAERP | I101: TURQUI | J101: RESERVA | K101: =VLOOKUP(I101,'LISTA DE ATLETAS'!D:E,2,FALSE) -> 1 | L101: 32 | M101: =(ATLETAS[2PM]*2)+(ATLETAS[3PM]*3)+(ATLETAS[FTM]) -> 0 | N101: =ATLETAS[2PM]+ATLETAS[3PM] -> 0 | O101: =ATLETAS[2PA]+ATLETAS[3PA] -> 0 | P101: =IFERROR(ATLETAS[FGM]/ATLETAS[FGA],"") | Q101: 0 | R101: 0 | S101: =IFERROR(ATLETAS[2PM]/ATLETAS[2PA],"") | T101: 0 | U101: 0 | V101: =IFERROR(ATLETAS[3PM]/ATLETAS[3PA],"") | W101: 0 | X101: 0 | Y101: =IFERROR(ATLETAS[FTM]/ATLETAS[FTA],"") | Z101: 0 | AA101: 0 | AB101: =ATLETAS[REB O]+ATLETAS[REB D] -> 0 | AC101: 0 | AD101: 1 | AE101: 0 | AF101: 0 | AG101: 0 | AH101: 0 | AI101: 0 | AJ101: =ATLETAS[PONTOS]+ATLETAS[TOTAL REB]+ATLETAS[AST]+ATLETAS[TOCOS]+ATLETAS[ROUB]-(ATLETAS[FGA]-ATLETAS[FGM])-(ATLETAS[FTA]-ATLETAS[FTM])-ATLETAS[ERROS] -> -1
A102: 83 | B102: 5 | C102: REGULAR | D102: 45964 | E102: NOVEMBRO | F102: 2025 | G102: LUS USP RP | H102: FILÔ USP RP | I102: LOBA | J102: TITULAR | K102: =VLOOKUP(I102,'LISTA DE ATLETAS'!D:E,2,FALSE) | L102: 8 | M102: =(ATLETAS[2PM]*2)+(ATLETAS[3PM]*3)+(ATLETAS[FTM]) -> 0 | N102: =ATLETAS[2PM]+ATLETAS[3PM] -> 0 | O102: =ATLETAS[2PA]+ATLETAS[3PA] -> 3 | P102: =IFERROR(ATLETAS[FGM]/ATLETAS[FGA],"") -> 0 | Q102: 0 | R102: 3 | S102: =IFERROR(ATLETAS[2PM]/ATLETAS[2PA],"") -> 0 | T102: 0 | U102: 0 | V102: =IFERROR(ATLETAS[3PM]/ATLETAS[3PA],"") | W102: 0 | X102: 0 | Y102: =IFERROR(ATLETAS[FTM]/ATLETAS[FTA],"") | Z102: 0 | AA102: 2 | AB102: =ATLETAS[REB O]+ATLETAS[REB D] -> 2 | AC102: 0 | AD102: 3 | AE102: 1 | AF102: 0 | AG102: 2 | AH102: 0 | AI102: -6 | AJ102: =ATLETAS[PONTOS]+ATLETAS[TOTAL REB]+ATLETAS[AST]+ATLETAS[TOCOS]+ATLETAS[ROUB]-(ATLETAS[FGA]-ATLETAS[FGM])-(ATLETAS[FTA]-ATLETAS[FTM])-ATLETAS[ERROS] -> -3
A103: 84 | B103: 5 | C103: REGULAR | D103: 45964 | E103: NOVEMBRO | F103: 2025 | G103: LUS USP RP | H103: FILÔ USP RP | I103: CHARLIE | J103: TITULAR | K103: =VLOOKUP(I103,'LISTA DE ATLETAS'!D:E,2,FALSE) | L103: 11 | M103: =(ATLETAS[2PM]*2)+(ATLETAS[3PM]*3)+(ATLETAS[FTM]) -> 0 | N103: =ATLETAS[2PM]+ATLETAS[3PM] -> 0 | O103: =ATLETAS[2PA]+ATLETAS[3PA] -> 5 | P103: =IFERROR(ATLETAS[FGM]/ATLETAS[FGA],"") -> 0 | Q103: 0 | R103: 5 | S103: =IFERROR(ATLETAS[2PM]/ATLETAS[2PA],"") -> 0 | T103: 0 | U103: 0 | V103: =IFERROR(ATLETAS[3PM]/ATLETAS[3PA],"") | W103: 0 | X103: 0 | Y103: =IFERROR(ATLETAS[FTM]/ATLETAS[FTA],"") | Z103: 0 | AA103: 2 | AB103: =ATLETAS[REB O]+ATLETAS[REB D] -> 2 | AC103: 0 | AD103: 2 | AE103: 1 | AF103: 0 | AG103: 2 | AH103: 0 | AI103: -14 | AJ103: =ATLETAS[PONTOS]+ATLETAS[TOTAL REB]+ATLETAS[AST]+ATLETAS[TOCOS]+ATLETAS[ROUB]-(ATLETAS[FGA]-ATLETAS[FGM])-(ATLETAS[FTA]-ATLETAS[FTM])-ATLETAS[ERROS] -> -4
A104: 87 | B104: 5 | C104: REGULAR | D104: 45964 | E104: NOVEMBRO | F104: 2025 | G104: LUS USP RP | H104: FILÔ USP RP | I104: MARIÊ | J104: RESERVA | K104: =VLOOKUP(I104,'LISTA DE ATLETAS'!D:E,2,FALSE) | L104: 94 | M104: =(ATLETAS[2PM]*2)+(ATLETAS[3PM]*3)+(ATLETAS[FTM]) -> 0 | N104: =ATLETAS[2PM]+ATLETAS[3PM] -> 0 | O104: =ATLETAS[2PA]+ATLETAS[3PA] -> 0 | P104: =IFERROR(ATLETAS[FGM]/ATLETAS[FGA],"") | Q104: 0 | R104: 0 | S104: =IFERROR(ATLETAS[2PM]/ATLETAS[2PA],"") | T104: 0 | U104: 0 | V104: =IFERROR(ATLETAS[3PM]/ATLETAS[3PA],"") | W104: 0 | X104: 0 | Y104: =IFERROR(ATLETAS[FTM]/ATLETAS[FTA],"") | Z104: 0 | AA104: 1 | AB104: =ATLETAS[REB O]+ATLETAS[REB D] -> 1 | AC104: 0 | AD104: 0 | AE104: 0 | AF104: 0 | AG104: 1 | AH104: 0 | AI104: 2 | AJ104: =ATLETAS[PONTOS]+ATLETAS[TOTAL REB]+ATLETAS[AST]+ATLETAS[TOCOS]+ATLETAS[ROUB]-(ATLETAS[FGA]-ATLETAS[FGM])-(ATLETAS[FTA]-ATLETAS[FTM])-ATLETAS[ERROS] -> 1
A105: 95 | B105: 5 | C105: REGULAR | D105: 45964 | E105: NOVEMBRO | F105: 2025 | G105: FILÔ USP RP | H105: LUS USP RP | I105: PONTUAL | J105: RESERVA | K105: =VLOOKUP(I105,'LISTA DE ATLETAS'!D:E,2,FALSE) | L105: 33 | M105: =(ATLETAS[2PM]*2)+(ATLETAS[3PM]*3)+(ATLETAS[FTM]) -> 0 | N105: =ATLETAS[2PM]+ATLETAS[3PM] -> 0 | O105: =ATLETAS[2PA]+ATLETAS[3PA] -> 4 | P105: =IFERROR(ATLETAS[FGM]/ATLETAS[FGA],"") -> 0 | Q105: 0 | R105: 4 | S105: =IFERROR(ATLETAS[2PM]/ATLETAS[2PA],"") -> 0 | T105: 0 | U105: 0 | V105: =IFERROR(ATLETAS[3PM]/ATLETAS[3PA],"") | W105: 0 | X105: 0 | Y105: =IFERROR(ATLETAS[FTM]/ATLETAS[FTA],"") | Z105: 2 | AA105: 3 | AB105: =ATLETAS[REB O]+ATLETAS[REB D] -> 5 | AC105: 0 | AD105: 1 | AE105: 0 | AF105: 1 | AG105: 0 | AH105: 0 | AI105: 2 | AJ105: =ATLETAS[PONTOS]+ATLETAS[TOTAL REB]+ATLETAS[AST]+ATLETAS[TOCOS]+ATLETAS[ROUB]-(ATLETAS[FGA]-ATLETAS[FGM])-(ATLETAS[FTA]-ATLETAS[FTM])-ATLETAS[ERROS] -> 1
A106: 96 | B106: 6 | C106: REGULAR | D106: 45971 | E106: NOVEMBRO | F106: 2025 | G106: LUS USP RP | H106: MED UNAERP | I106: PURURUCA | J106: TITULAR | K106: =VLOOKUP(I106,'LISTA DE ATLETAS'!D:E,2,FALSE) | L106: 7 | M106: =(ATLETAS[2PM]*2)+(ATLETAS[3PM]*3)+(ATLETAS[FTM]) -> 0 | N106: =ATLETAS[2PM]+ATLETAS[3PM] -> 0 | O106: =ATLETAS[2PA]+ATLETAS[3PA] -> 3 | P106: =IFERROR(ATLETAS[FGM]/ATLETAS[FGA],"") -> 0 | Q106: 0 | R106: 3 | S106: =IFERROR(ATLETAS[2PM]/ATLETAS[2PA],"") -> 0 | T106: 0 | U106: 0 | V106: =IFERROR(ATLETAS[3PM]/ATLETAS[3PA],"") | W106: 0 | X106: 2 | Y106: =IFERROR(ATLETAS[FTM]/ATLETAS[FTA],"") -> 0 | Z106: 1 | AA106: 1 | AB106: =ATLETAS[REB O]+ATLETAS[REB D] -> 2 | AC106: 1 | AD106: 1 | AE106: 0 | AF106: 0 | AG106: 2 | AH106: 1 | AI106: 11 | AJ106: =ATLETAS[PONTOS]+ATLETAS[TOTAL REB]+ATLETAS[AST]+ATLETAS[TOCOS]+ATLETAS[ROUB]-(ATLETAS[FGA]-ATLETAS[FGM])-(ATLETAS[FTA]-ATLETAS[FTM])-ATLETAS[ERROS] -> -3
A107: 97 | B107: 6 | C107: REGULAR | D107: 45971 | E107: NOVEMBRO | F107: 2025 | G107: LUS USP RP | H107: MED UNAERP | I107: LOBA | J107: TITULAR | K107: =VLOOKUP(I107,'LISTA DE ATLETAS'!D:E,2,FALSE) | L107: 8 | M107: =(ATLETAS[2PM]*2)+(ATLETAS[3PM]*3)+(ATLETAS[FTM]) -> 0 | N107: =ATLETAS[2PM]+ATLETAS[3PM] -> 0 | O107: =ATLETAS[2PA]+ATLETAS[3PA] -> 8 | P107: =IFERROR(ATLETAS[FGM]/ATLETAS[FGA],"") -> 0 | Q107: 0 | R107: 8 | S107: =IFERROR(ATLETAS[2PM]/ATLETAS[2PA],"") -> 0 | T107: 0 | U107: 0 | V107: =IFERROR(ATLETAS[3PM]/ATLETAS[3PA],"") | W107: 0 | X107: 0 | Y107: =IFERROR(ATLETAS[FTM]/ATLETAS[FTA],"") | Z107: 2 | AA107: 1 | AB107: =ATLETAS[REB O]+ATLETAS[REB D] -> 3 | AC107: 0 | AD107: 3 | AE107: 4 | AF107: 2 | AG107: 0 | AH107: 0 | AI107: 6 | AJ107: =ATLETAS[PONTOS]+ATLETAS[TOTAL REB]+ATLETAS[AST]+ATLETAS[TOCOS]+ATLETAS[ROUB]-(ATLETAS[FGA]-ATLETAS[FGM])-(ATLETAS[FTA]-ATLETAS[FTM])-ATLETAS[ERROS] -> -2
A108: 99 | B108: 6 | C108: REGULAR | D108: 45971 | E108: NOVEMBRO | F108: 2025 | G108: LUS USP RP | H108: MED UNAERP | I108: MABS | J108: TITULAR | K108: =VLOOKUP(I108,'LISTA DE ATLETAS'!D:E,2,FALSE) | L108: 24 | M108: =(ATLETAS[2PM]*2)+(ATLETAS[3PM]*3)+(ATLETAS[FTM]) -> 0 | N108: =ATLETAS[2PM]+ATLETAS[3PM] -> 0 | O108: =ATLETAS[2PA]+ATLETAS[3PA] -> 1 | P108: =IFERROR(ATLETAS[FGM]/ATLETAS[FGA],"") -> 0 | Q108: 0 | R108: 1 | S108: =IFERROR(ATLETAS[2PM]/ATLETAS[2PA],"") -> 0 | T108: 0 | U108: 0 | V108: =IFERROR(ATLETAS[3PM]/ATLETAS[3PA],"") | W108: 0 | X108: 0 | Y108: =IFERROR(ATLETAS[FTM]/ATLETAS[FTA],"") | Z108: 1 | AA108: 1 | AB108: =ATLETAS[REB O]+ATLETAS[REB D] -> 2 | AC108: 0 | AD108: 0 | AE108: 0 | AF108: 0 | AG108: 1 | AH108: 0 | AI108: 3 | AJ108: =ATLETAS[PONTOS]+ATLETAS[TOTAL REB]+ATLETAS[AST]+ATLETAS[TOCOS]+ATLETAS[ROUB]-(ATLETAS[FGA]-ATLETAS[FGM])-(ATLETAS[FTA]-ATLETAS[FTM])-ATLETAS[ERROS] -> 1
... A112: 108 | B112: 6 | C112: REGULAR | D112: 45971 | E112: NOVEMBRO | F112: 2025 | G112: MED UNAERP | H112: LUS USP RP | I112: GALVÃO | J112: TITULAR | K112: =VLOOKUP(I112,'LISTA DE ATLETAS'!D:E,2,FALSE) | L112: 22 | M112: =(ATLETAS[2PM]*2)+(ATLETAS[3PM]*3)+(ATLETAS[FTM]) -> 0 | N112: =ATLETAS[2PM]+ATLETAS[3PM] -> 0 | O112: =ATLETAS[2PA]+ATLETAS[3PA] -> 0 | P112: =IFERROR(ATLETAS[FGM]/ATLETAS[FGA],"") | Q112: 0 | R112: 0 | S112: =IFERROR(ATLETAS[2PM]/ATLETAS[2PA],"") | T112: 0 | U112: 0 | V112: =IFERROR(ATLETAS[3PM]/ATLETAS[3PA],"") | W112: 0 | X112: 0 | Y112: =IFERROR(ATLETAS[FTM]/ATLETAS[FTA],"") | Z112: 0 | AA112: 1 | AB112: =ATLETAS[REB O]+ATLETAS[REB D] -> 1 | AC112: 0 | AD112: 2 | AE112: 0 | AF112: 0 | AG112: 2 | AH112: 1 | AI112: -5 | AJ112: =ATLETAS[PONTOS]+ATLETAS[TOTAL REB]+ATLETAS[AST]+ATLETAS[TOCOS]+ATLETAS[ROUB]-(ATLETAS[FGA]-ATLETAS[FGM])-(ATLETAS[FTA]-ATLETAS[FTM])-ATLETAS[ERROS] -> -1

Sheet DINÂMICA ESTATÍSTICAS ATLETAS

Sheet ESTATÍSTICAS EQUIPES
A1: CÉLULA | B1: JOGO | C1: DATA | D1: MÊS | E1: ANO | F1: EQUIPE | G1: TÉCNICO | H1: ADVERSÁRIO | I1: PONTOS SOFRIDOS | J1: PONTOS MARCADOS | K1: RESULTADO | L1: FGM | M1: FGA | N1: %FG | O1: 2PM | P1: 2PA | Q1: %2P | R1: 3PM | S1: 3PA | T1: %3P | U1: FTM | V1: FTA | W1: %FT | X1: REB O | Y1: REB D | Z1: TOTAL REB | AA1: AST | AB1: ERROS | AC1: ROUB | AD1: TOCOS | AE1: FALTAS C | AF1: FALTAS S | AG1: PLUS/MINUS | AH1: EFICIÊNCIA
A2: 1 | B2: 1 | C2: 45896 | D2: AGOSTO | E2: 2025 | F2: LUS USP RP | G2: JATO | H2: FILÔ USP RP | I2: 19 | J2: =(Tabela_2[2PM]*2)+(Tabela_2[3PM]*3)+(Tabela_2[FTM]) -> 14 | K2: DERROTA | L2: =Tabela_2[2PM]+Tabela_2[3PM] -> 5 | M2: =Tabela_2[2PA]+Tabela_2[3PA] -> 75 | N2: =IFERROR(Tabela_2[FGM]/Tabela_2[FGA],"") -> 0.066666667 | O2: 4 | P2: 57 | Q2: =IFERROR(Tabela_2[2PM]/Tabela_2[2PA],"") -> 0.070175439 | R2: 1 | S2: 18 | T2: =IFERROR(ATLETAS[3PM]/ATLETAS[3PA],"") | U2: 3 | V2: 10 | W2: =IFERROR(Tabela_2[FTM]/Tabela_2[FTA],"") -> 0.3 | X2: 29 | Y2: 27 | Z2: =Tabela_2[REB O]+Tabela_2[REB D] -> 56 | AA2: 5 | AB2: 29 | AC2: 27 | AD2: 2 | AE2: 8 | AF2: 9 | AG2: -5 | AH2: =Tabela_2[PONTOS MARCADOS]+Tabela_2[TOTAL REB]+Tabela_2[AST]+Tabela_2[TOCOS]-(Tabela_2[FGA]-Tabela_2[FGM])-(Tabela_2[FTA]-Tabela_2[FTM])-Tabela_2[ERROS]+Tabela_2[ROUB] -> -2
